Workbook
Name Áreadeimpresión: 'Planilla de control'!$A$1:$M$2

Sheet Referencias
A1: Referencias:
A2: A - La ubicación está vacía y en sistema figura ocupada
A3: B - La ubicación está ocupada y en sistema figura vacía
A4: C - El material que se encuentra en la ubicación no coincide con el material que aparece en sistema
A5: D - Error de cantidad

Sheet BORRADOR
A1: DATOS SAP
A2: Tipo almacén | B2: Ubicación | C2: Material | D2: Unidad almacén | E2: Bloqueo de entradas | F2: Stock disponible | G2: Stock a entrar | H2: Motivo bloqueo | I2: calle, modulo y nivel | J2: Nivel | K2: Calle | L2: Alveolo | M2: Deposito
A3: PC5 | B3: 21A1A | C3: 02A311351ASS00 | D3: 09001450548127 | F3: 960 | G3: 0 | I3: =IF(OR(LEN(B3)=9,LEN(B3)=5),MID(B3,1,4),MID(B3,1,5)) -> 21A1 | J3: =IF(MID(I3,5,1)<>"",MID(I3,4,2),MID(I3,4,1))*1 -> 1 | K3: =+MID(B3,1,2)*1 -> 21 | L3: =+MID(B3,3,1) -> A | M3: =+IF(A3="1FO","D3",IF(A3="1CT","D4",IF(OR(A3="PC2",A3="RAB"),"MQ200","MQ250"))) -> MQ250
A4: PC5 | B4: 21A1B | C4: 02A311291K0S02 | D4: 09001441718893 | F4: 600 | G4: 0 | I4: =IF(OR(LEN(B4)=9,LEN(B4)=5),MID(B4,1,4),MID(B4,1,5)) -> 21A1 | J4: =IF(MID(I4,5,1)<>"",MID(I4,4,2),MID(I4,4,1))*1 -> 1 | K4: =+MID(B4,1,2)*1 -> 21 | L4: =+MID(B4,3,1) -> A | M4: =+IF(A4="1FO","D3",IF(A4="1CT","D4",IF(OR(A4="PC2",A4="RAB"),"MQ200","MQ250"))) -> MQ250
A5: PC5 | B5: 21A1C | C5: << vacías >> | F5: 0 | G5: 0 | I5: =IF(OR(LEN(B5)=9,LEN(B5)=5),MID(B5,1,4),MID(B5,1,5)) -> 21A1 | J5: =IF(MID(I5,5,1)<>"",MID(I5,4,2),MID(I5,4,1))*1 -> 1 | K5: =+MID(B5,1,2)*1 -> 21 | L5: =+MID(B5,3,1) -> A | M5: =+IF(A5="1FO","D3",IF(A5="1CT","D4",IF(OR(A5="PC2",A5="RAB"),"MQ200","MQ250"))) -> MQ250
A6: PC5 | B6: 21A2A | C6: 02A311149B0S00 | D6: 09001442244588 | F6: 924 | G6: 0 | I6: =IF(OR(LEN(B6)=9,LEN(B6)=5),MID(B6,1,4),MID(B6,1,5)) -> 21A2 | J6: =IF(MID(I6,5,1)<>"",MID(I6,4,2),MID(I6,4,1))*1 -> 2 | K6: =+MID(B6,1,2)*1 -> 21 | L6: =+MID(B6,3,1) -> A | M6: =+IF(A6="1FO","D3",IF(A6="1CT","D4",IF(OR(A6="PC2",A6="RAB"),"MQ200","MQ250"))) -> MQ250
A7: PC5 | B7: 21A2B | C7: 02A311285BCS00 | D7: 09001450548206 | F7: 960 | G7: 0 | I7: =IF(OR(LEN(B7)=9,LEN(B7)=5),MID(B7,1,4),MID(B7,1,5)) -> 21A2 | J7: =IF(MID(I7,5,1)<>"",MID(I7,4,2),MID(I7,4,1))*1 -> 2 | K7: =+MID(B7,1,2)*1 -> 21 | L7: =+MID(B7,3,1) -> A | M7: =+IF(A7="1FO","D3",IF(A7="1CT","D4",IF(OR(A7="PC2",A7="RAB"),"MQ200","MQ250"))) -> MQ250
A8: PC5 | B8: 21A2C | C8: 02J31125500S07 | D8: 09001447654953 | F8: 378 | G8: 0 | I8: =IF(OR(LEN(B8)=9,LEN(B8)=5),MID(B8,1,4),MID(B8,1,5)) -> 21A2 | J8: =IF(MID(I8,5,1)<>"",MID(I8,4,2),MID(I8,4,1))*1 -> 2 | K8: =+MID(B8,1,2)*1 -> 21 | L8: =+MID(B8,3,1) -> A | M8: =+IF(A8="1FO","D3",IF(A8="1CT","D4",IF(OR(A8="PC2",A8="RAB"),"MQ200","MQ250"))) -> MQ250
A9: PC5 | B9: 21A3A | C9: 02J31125500S07 | D9: 09001450358496 | F9: 0 | G9: 378 | I9: =IF(OR(LEN(B9)=9,LEN(B9)=5),MID(B9,1,4),MID(B9,1,5)) -> 21A3 | J9: =IF(MID(I9,5,1)<>"",MID(I9,4,2),MID(I9,4,1))*1 -> 3 | K9: =+MID(B9,1,2)*1 -> 21 | L9: =+MID(B9,3,1) -> A | M9: =+IF(A9="1FO","D3",IF(A9="1CT","D4",IF(OR(A9="PC2",A9="RAB"),"MQ200","MQ250"))) -> MQ250
A10: PC5 | B10: 21A3B | C10: 02A31136500S04 | D10: 09001448137118 | F10: 636 | G10: 0 | I10: =IF(OR(LEN(B10)=9,LEN(B10)=5),MID(B10,1,4),MID(B10,1,5)) -> 21A3 | J10: =IF(MID(I10,5,1)<>"",MID(I10,4,2),MID(I10,4,1))*1 -> 3 | K10: =+MID(B10,1,2)*1 -> 21 | L10: =+MID(B10,3,1) -> A | M10: =+IF(A10="1FO","D3",IF(A10="1CT","D4",IF(OR(A10="PC2",A10="RAB"),"MQ200","MQ250"))) -> MQ250
A11: PC5 | B11: 21A3C | C11: 02J31125500S07 | D11: 09001447522585 | F11: 378 | G11: 0 | I11: =IF(OR(LEN(B11)=9,LEN(B11)=5),MID(B11,1,4),MID(B11,1,5)) -> 21A3 | J11: =IF(MID(I11,5,1)<>"",MID(I11,4,2),MID(I11,4,1))*1 -> 3 | K11: =+MID(B11,1,2)*1 -> 21 | L11: =+MID(B11,3,1) -> A | M11: =+IF(A11="1FO","D3",IF(A11="1CT","D4",IF(OR(A11="PC2",A11="RAB"),"MQ200","MQ250"))) -> MQ250
A12: PC5 | B12: 21A4A | C12: 02A311291J0S02 | D12: 09001450677586 | F12: 700 | G12: 0 | I12: =IF(OR(LEN(B12)=9,LEN(B12)=5),MID(B12,1,4),MID(B12,1,5)) -> 21A4 | J12: =IF(MID(I12,5,1)<>"",MID(I12,4,2),MID(I12,4,1))*1 -> 4 | K12: =+MID(B12,1,2)*1 -> 21 | L12: =+MID(B12,3,1) -> A | M12: =+IF(A12="1FO","D3",IF(A12="1CT","D4",IF(OR(A12="PC2",A12="RAB"),"MQ200","MQ250"))) -> MQ250
A13: PC5 | B13: 21A4B | C13: 02A31136500S04 | D13: 09001447654956 | F13: 288 | G13: 0 | I13: =IF(OR(LEN(B13)=9,LEN(B13)=5),MID(B13,1,4),MID(B13,1,5)) -> 21A4 | J13: =IF(MID(I13,5,1)<>"",MID(I13,4,2),MID(I13,4,1))*1 -> 4 | K13: =+MID(B13,1,2)*1 -> 21 | L13: =+MID(B13,3,1) -> A | M13: =+IF(A13="1FO","D3",IF(A13="1CT","D4",IF(OR(A13="PC2",A13="RAB"),"MQ200","MQ250"))) -> MQ250
A14: PC5 | B14: 21A4C | C14: 02A31136500S04 | D14: 09001448160442 | F14: 600 | G14: 0 | I14: =IF(OR(LEN(B14)=9,LEN(B14)=5),MID(B14,1,4),MID(B14,1,5)) -> 21A4 | J14: =IF(MID(I14,5,1)<>"",MID(I14,4,2),MID(I14,4,1))*1 -> 4 | K14: =+MID(B14,1,2)*1 -> 21 | L14: =+MID(B14,3,1) -> A | M14: =+IF(A14="1FO","D3",IF(A14="1CT","D4",IF(OR(A14="PC2",A14="RAB"),"MQ200","MQ250"))) -> MQ250
A15: PC5 | B15: 21A5A | C15: 02A31136500S04 | D15: 09001448160443 | F15: 600 | G15: 0 | I15: =IF(OR(LEN(B15)=9,LEN(B15)=5),MID(B15,1,4),MID(B15,1,5)) -> 21A5 | J15: =IF(MID(I15,5,1)<>"",MID(I15,4,2),MID(I15,4,1))*1 -> 5 | K15: =+MID(B15,1,2)*1 -> 21 | L15: =+MID(B15,3,1) -> A | M15: =+IF(A15="1FO","D3",IF(A15="1CT","D4",IF(OR(A15="PC2",A15="RAB"),"MQ200","MQ250"))) -> MQ250
A16: RPK | B16: 21A5A | C16: << vacías >> | E16: X | F16: 0 | G16: 0 | H16: G | I16: =IF(OR(LEN(B16)=9,LEN(B16)=5),MID(B16,1,4),MID(B16,1,5)) -> 21A5 | J16: =IF(MID(I16,5,1)<>"",MID(I16,4,2),MID(I16,4,1))*1 -> 5 | K16: =+MID(B16,1,2)*1 -> 21 | L16: =+MID(B16,3,1) -> A | M16: =+IF(A16="1FO","D3",IF(A16="1CT","D4",IF(OR(A16="PC2",A16="RAB"),"MQ200","MQ250"))) -> MQ250
A17: PC5 | B17: 21A5B | C17: 02A311149AMS00 | D17: 09001450125550 | F17: 832 | G17: 0 | I17: =IF(OR(LEN(B17)=9,LEN(B17)=5),MID(B17,1,4),MID(B17,1,5)) -> 21A5 | J17: =IF(MID(I17,5,1)<>"",MID(I17,4,2),MID(I17,4,1))*1 -> 5 | K17: =+MID(B17,1,2)*1 -> 21 | L17: =+MID(B17,3,1) -> A | M17: =+IF(A17="1FO","D3",IF(A17="1CT","D4",IF(OR(A17="PC2",A17="RAB"),"MQ200","MQ250"))) -> MQ250
A18: PC5 | B18: 21A5C | C18: 02A311291J0S02 | D18: 09001450677587 | F18: 700 | G18: 0 | I18: =IF(OR(LEN(B18)=9,LEN(B18)=5),MID(B18,1,4),MID(B18,1,5)) -> 21A5 | J18: =IF(MID(I18,5,1)<>"",MID(I18,4,2),MID(I18,4,1))*1 -> 5 | K18: =+MID(B18,1,2)*1 -> 21 | L18: =+MID(B18,3,1) -> A | M18: =+IF(A18="1FO","D3",IF(A18="1CT","D4",IF(OR(A18="PC2",A18="RAB"),"MQ200","MQ250"))) -> MQ250
A19: PC5 | B19: 21A6A | C19: 02J31125500S07 | D19: 09001450358497 | F19: 0 | G19: 378 | I19: =IF(OR(LEN(B19)=9,LEN(B19)=5),MID(B19,1,4),MID(B19,1,5)) -> 21A6 | J19: =IF(MID(I19,5,1)<>"",MID(I19,4,2),MID(I19,4,1))*1 -> 6 | K19: =+MID(B19,1,2)*1 -> 21 | L19: =+MID(B19,3,1) -> A | M19: =+IF(A19="1FO","D3",IF(A19="1CT","D4",IF(OR(A19="PC2",A19="RAB"),"MQ200","MQ250"))) -> MQ250
A20: RPK | B20: 21A6A | C20: << vacías >> | E20: X | F20: 0 | G20: 0 | H20: G | I20: =IF(OR(LEN(B20)=9,LEN(B20)=5),MID(B20,1,4),MID(B20,1,5)) -> 21A6 | J20: =IF(MID(I20,5,1)<>"",MID(I20,4,2),MID(I20,4,1))*1 -> 6 | K20: =+MID(B20,1,2)*1 -> 21 | L20: =+MID(B20,3,1) -> A | M20: =+IF(A20="1FO","D3",IF(A20="1CT","D4",IF(OR(A20="PC2",A20="RAB"),"MQ200","MQ250"))) -> MQ250
A21: PC5 | B21: 21A6B | C21: 02J31125500S07 | D21: 09001450358498 | F21: 0 | G21: 378 | I21: =IF(OR(LEN(B21)=9,LEN(B21)=5),MID(B21,1,4),MID(B21,1,5)) -> 21A6 | J21: =IF(MID(I21,5,1)<>"",MID(I21,4,2),MID(I21,4,1))*1 -> 6 | K21: =+MID(B21,1,2)*1 -> 21 | L21: =+MID(B21,3,1) -> A | M21: =+IF(A21="1FO","D3",IF(A21="1CT","D4",IF(OR(A21="PC2",A21="RAB"),"MQ200","MQ250"))) -> MQ250
A22: RPK | B22: 21A6B | C22: << vacías >> | E22: X | F22: 0 | G22: 0 | H22: G | I22: =IF(OR(LEN(B22)=9,LEN(B22)=5),MID(B22,1,4),MID(B22,1,5)) -> 21A6 | J22: =IF(MID(I22,5,1)<>"",MID(I22,4,2),MID(I22,4,1))*1 -> 6 | K22: =+MID(B22,1,2)*1 -> 21 | L22: =+MID(B22,3,1) -> A | M22: =+IF(A22="1FO","D3",IF(A22="1CT","D4",IF(OR(A22="PC2",A22="RAB"),"MQ200","MQ250"))) -> MQ250
A23: PC5 | B23: 21A6C | C23: 02J31125500S07 | D23: 09001450385048 | F23: 0 | G23: 378 | I23: =IF(OR(LEN(B23)=9,LEN(B23)=5),MID(B23,1,4),MID(B23,1,5)) -> 21A6 | J23: =IF(MID(I23,5,1)<>"",MID(I23,4,2),MID(I23,4,1))*1 -> 6 | K23: =+MID(B23,1,2)*1 -> 21 | L23: =+MID(B23,3,1) -> A | M23: =+IF(A23="1FO","D3",IF(A23="1CT","D4",IF(OR(A23="PC2",A23="RAB"),"MQ200","MQ250"))) -> MQ250
A24: RPK | B24: 21A6C | C24: << vacías >> | E24: X | F24: 0 | G24: 0 | H24: G | I24: =IF(OR(LEN(B24)=9,LEN(B24)=5),MID(B24,1,4),MID(B24,1,5)) -> 21A6 | J24: =IF(MID(I24,5,1)<>"",MID(I24,4,2),MID(I24,4,1))*1 -> 6 | K24: =+MID(B24,1,2)*1 -> 21 | L24: =+MID(B24,3,1) -> A | M24: =+IF(A24="1FO","D3",IF(A24="1CT","D4",IF(OR(A24="PC2",A24="RAB"),"MQ200","MQ250"))) -> MQ250
A25: PC5 | B25: 21A7A | C25: 02A311149AMS00 | D25: 09001449915810 | F25: 832 | G25: 0 | I25: =IF(OR(LEN(B25)=9,LEN(B25)=5),MID(B25,1,4),MID(B25,1,5)) -> 21A7 | J25: =IF(MID(I25,5,1)<>"",MID(I25,4,2),MID(I25,4,1))*1 -> 7 | K25: =+MID(B25,1,2)*1 -> 21 | L25: =+MID(B25,3,1) -> A | M25: =+IF(A25="1FO","D3",IF(A25="1CT","D4",IF(OR(A25="PC2",A25="RAB"),"MQ200","MQ250"))) -> MQ250
A26: RPK | B26: 21A7A | C26: << vacías >> | E26: X | F26: 0 | G26: 0 | H26: G | I26: =IF(OR(LEN(B26)=9,LEN(B26)=5),MID(B26,1,4),MID(B26,1,5)) -> 21A7 | J26: =IF(MID(I26,5,1)<>"",MID(I26,4,2),MID(I26,4,1))*1 -> 7 | K26: =+MID(B26,1,2)*1 -> 21 | L26: =+MID(B26,3,1) -> A | M26: =+IF(A26="1FO","D3",IF(A26="1CT","D4",IF(OR(A26="PC2",A26="RAB"),"MQ200","MQ250"))) -> MQ250
A27: PC5 | B27: 21A7B | C27: 02A311291J0S02 | D27: 09001450420204 | F27: 700 | G27: 0 | I27: =IF(OR(LEN(B27)=9,LEN(B27)=5),MID(B27,1,4),MID(B27,1,5)) -> 21A7 | J27: =IF(MID(I27,5,1)<>"",MID(I27,4,2),MID(I27,4,1))*1 -> 7 | K27: =+MID(B27,1,2)*1 -> 21 | L27: =+MID(B27,3,1) -> A | M27: =+IF(A27="1FO","D3",IF(A27="1CT","D4",IF(OR(A27="PC2",A27="RAB"),"MQ200","MQ250"))) -> MQ250
A28: RPK | B28: 21A7B | C28: << vacías >> | E28: X | F28: 0 | G28: 0 | H28: G | I28: =IF(OR(LEN(B28)=9,LEN(B28)=5),MID(B28,1,4),MID(B28,1,5)) -> 21A7 | J28: =IF(MID(I28,5,1)<>"",MID(I28,4,2),MID(I28,4,1))*1 -> 7 | K28: =+MID(B28,1,2)*1 -> 21 | L28: =+MID(B28,3,1) -> A | M28: =+IF(A28="1FO","D3",IF(A28="1CT","D4",IF(OR(A28="PC2",A28="RAB"),"MQ200","MQ250"))) -> MQ250
A29: PC5 | B29: 21A7C | C29: 02A311291J0S02 | D29: 09001450501445 | F29: 700 | G29: 0 | I29: =IF(OR(LEN(B29)=9,LEN(B29)=5),MID(B29,1,4),MID(B29,1,5)) -> 21A7 | J29: =IF(MID(I29,5,1)<>"",MID(I29,4,2),MID(I29,4,1))*1 -> 7 | K29: =+MID(B29,1,2)*1 -> 21 | L29: =+MID(B29,3,1) -> A | M29: =+IF(A29="1FO","D3",IF(A29="1CT","D4",IF(OR(A29="PC2",A29="RAB"),"MQ200","MQ250"))) -> MQ250
A30: RPK | B30: 21A7C | C30: << vacías >> | E30: X | F30: 0 | G30: 0 | H30: G | I30: =IF(OR(LEN(B30)=9,LEN(B30)=5),MID(B30,1,4),MID(B30,1,5)) -> 21A7 | J30: =IF(MID(I30,5,1)<>"",MID(I30,4,2),MID(I30,4,1))*1 -> 7 | K30: =+MID(B30,1,2)*1 -> 21 | L30: =+MID(B30,3,1) -> A | M30: =+IF(A30="1FO","D3",IF(A30="1CT","D4",IF(OR(A30="PC2",A30="RAB"),"MQ200","MQ250"))) -> MQ250
A31: PC5 | B31: 21A8A | C31: 02J31125500S07 | D31: 09001450420051 | F31: 0 | G31: 378 | I31: =IF(OR(LEN(B31)=9,LEN(B31)=5),MID(B31,1,4),MID(B31,1,5)) -> 21A8 | J31: =IF(MID(I31,5,1)<>"",MID(I31,4,2),MID(I31,4,1))*1 -> 8 | K31: =+MID(B31,1,2)*1 -> 21 | L31: =+MID(B31,3,1) -> A | M31: =+IF(A31="1FO","D3",IF(A31="1CT","D4",IF(OR(A31="PC2",A31="RAB"),"MQ200","MQ250"))) -> MQ250
A32: RPK | B32: 21A8A | C32: << vacías >> | E32: X | F32: 0 | G32: 0 | H32: G | I32: =IF(OR(LEN(B32)=9,LEN(B32)=5),MID(B32,1,4),MID(B32,1,5)) -> 21A8 | J32: =IF(MID(I32,5,1)<>"",MID(I32,4,2),MID(I32,4,1))*1 -> 8 | K32: =+MID(B32,1,2)*1 -> 21 | L32: =+MID(B32,3,1) -> A | M32: =+IF(A32="1FO","D3",IF(A32="1CT","D4",IF(OR(A32="PC2",A32="RAB"),"MQ200","MQ250"))) -> MQ250
A33: PC5 | B33: 21A8B | C33: 02J311103C0S10 | D33: 09001449051504 | F33: 105 | G33: 0 | I33: =IF(OR(LEN(B33)=9,LEN(B33)=5),MID(B33,1,4),MID(B33,1,5)) -> 21A8 | J33: =IF(MID(I33,5,1)<>"",MID(I33,4,2),MID(I33,4,1))*1 -> 8 | K33: =+MID(B33,1,2)*1 -> 21 | L33: =+MID(B33,3,1) -> A | M33: =+IF(A33="1FO","D3",IF(A33="1CT","D4",IF(OR(A33="PC2",A33="RAB"),"MQ200","MQ250"))) -> MQ250
A34: RPK | B34: 21A8B | C34: << vacías >> | E34: X | F34: 0 | G34: 0 | H34: G | I34: =IF(OR(LEN(B34)=9,LEN(B34)=5),MID(B34,1,4),MID(B34,1,5)) -> 21A8 | J34: =IF(MID(I34,5,1)<>"",MID(I34,4,2),MID(I34,4,1))*1 -> 8 | K34: =+MID(B34,1,2)*1 -> 21 | L34: =+MID(B34,3,1) -> A | M34: =+IF(A34="1FO","D3",IF(A34="1CT","D4",IF(OR(A34="PC2",A34="RAB"),"MQ200","MQ250"))) -> MQ250
A35: PC5 | B35: 21A8C | C35: 02J311103C0S10 | D35: 09001449051505 | F35: 105 | G35: 0 | I35: =IF(OR(LEN(B35)=9,LEN(B35)=5),MID(B35,1,4),MID(B35,1,5)) -> 21A8 | J35: =IF(MID(I35,5,1)<>"",MID(I35,4,2),MID(I35,4,1))*1 -> 8 | K35: =+MID(B35,1,2)*1 -> 21 | L35: =+MID(B35,3,1) -> A | M35: =+IF(A35="1FO","D3",IF(A35="1CT","D4",IF(OR(A35="PC2",A35="RAB"),"MQ200","MQ250"))) -> MQ250
A36: RPK | B36: 21A8C | C36: << vacías >> | E36: X | F36: 0 | G36: 0 | H36: G | I36: =IF(OR(LEN(B36)=9,LEN(B36)=5),MID(B36,1,4),MID(B36,1,5)) -> 21A8 | J36: =IF(MID(I36,5,1)<>"",MID(I36,4,2),MID(I36,4,1))*1 -> 8 | K36: =+MID(B36,1,2)*1 -> 21 | L36: =+MID(B36,3,1) -> A | M36: =+IF(A36="1FO","D3",IF(A36="1CT","D4",IF(OR(A36="PC2",A36="RAB"),"MQ200","MQ250"))) -> MQ250
A37: PC5 | B37: 21A9A | C37: << vacías >> | F37: 0 | G37: 0 | I37: =IF(OR(LEN(B37)=9,LEN(B37)=5),MID(B37,1,4),MID(B37,1,5)) -> 21A9 | J37: =IF(MID(I37,5,1)<>"",MID(I37,4,2),MID(I37,4,1))*1 -> 9 | K37: =+MID(B37,1,2)*1 -> 21 | L37: =+MID(B37,3,1) -> A | M37: =+IF(A37="1FO","D3",IF(A37="1CT","D4",IF(OR(A37="PC2",A37="RAB"),"MQ200","MQ250"))) -> MQ250
A38: RPK | B38: 21A9A | C38: << vacías >> | E38: X | F38: 0 | G38: 0 | H38: T | I38: =IF(OR(LEN(B38)=9,LEN(B38)=5),MID(B38,1,4),MID(B38,1,5)) -> 21A9 | J38: =IF(MID(I38,5,1)<>"",MID(I38,4,2),MID(I38,4,1))*1 -> 9 | K38: =+MID(B38,1,2)*1 -> 21 | L38: =+MID(B38,3,1) -> A | M38: =+IF(A38="1FO","D3",IF(A38="1CT","D4",IF(OR(A38="PC2",A38="RAB"),"MQ200","MQ250"))) -> MQ250
A39: PC5 | B39: 21A9B | C39: << vacías >> | F39: 0 | G39: 0 | I39: =IF(OR(LEN(B39)=9,LEN(B39)=5),MID(B39,1,4),MID(B39,1,5)) -> 21A9 | J39: =IF(MID(I39,5,1)<>"",MID(I39,4,2),MID(I39,4,1))*1 -> 9 | K39: =+MID(B39,1,2)*1 -> 21 | L39: =+MID(B39,3,1) -> A | M39: =+IF(A39="1FO","D3",IF(A39="1CT","D4",IF(OR(A39="PC2",A39="RAB"),"MQ200","MQ250"))) -> MQ250
A40: RPK | B40: 21A9B | C40: << vacías >> | E40: X | F40: 0 | G40: 0 | H40: T | I40: =IF(OR(LEN(B40)=9,LEN(B40)=5),MID(B40,1,4),MID(B40,1,5)) -> 21A9 | J40: =IF(MID(I40,5,1)<>"",MID(I40,4,2),MID(I40,4,1))*1 -> 9 | K40: =+MID(B40,1,2)*1 -> 21 | L40: =+MID(B40,3,1) -> A | M40: =+IF(A40="1FO","D3",IF(A40="1CT","D4",IF(OR(A40="PC2",A40="RAB"),"MQ200","MQ250"))) -> MQ250
...

Sheet dias
A1: fecha | B1: semana | C1: dia | D1: Cuenta | E1: mes | F1: conto? | H1: Feriados | K1: Cuenta | L1: (Todas) | P1: Etiquetas de fila | Q1: Sum of Cuenta | U1: Etiquetas de fila | V1: Sum of Cuenta
A2: 44927 | B2: =+WEEKNUM(A2) -> 1 | C2: =+WEEKDAY(A2,2) -> 7 | D2: =IF(AND(C2>=1,C2<=5,IFERROR(VLOOKUP(A2,$H$2:$H$10,1,0),0)=0),1,0) -> 0 | E2: =MONTH(A2) -> 1 | F2: =IF(IFERROR(VLOOKUP(A2,'Planilla de control'!#REF!,1,0),0)>0,1,0) -> 0 | P2: 8 | Q2: 23 | U2: 8 | V2: 23
A3: 44928 | B3: =+WEEKNUM(A3) -> 1 | C3: =+WEEKDAY(A3,2) -> 1 | D3: =IF(AND(C3>=1,C3<=5,IFERROR(VLOOKUP(A3,$H$2:$H$10,1,0),0)=0),1,0) -> 1 | E3: =MONTH(A3) -> 1 | F3: =IF(IFERROR(VLOOKUP(A3,'Planilla de control'!#REF!,1,0),0)>0,1,0) -> 0 | H3: 44977 | K3: Etiquetas de fila | L3: Sum of conto? | P3: 9 | Q3: 21 | U3: 32 | V3: 5
A4: 44929 | B4: =+WEEKNUM(A4) -> 1 | C4: =+WEEKDAY(A4,2) -> 2 | D4: =IF(AND(C4>=1,C4<=5,IFERROR(VLOOKUP(A4,$H$2:$H$10,1,0),0)=0),1,0) -> 1 | E4: =MONTH(A4) -> 1 | F4: =IF(IFERROR(VLOOKUP(A4,'Planilla de control'!#REF!,1,0),0)>0,1,0) -> 0 | H4: 44978 | K4: 8 | L4: 2 | P4: 10 | Q4: 22 | U4: 33 | V4: 5
A5: 44930 | B5: =+WEEKNUM(A5) -> 1 | C5: =+WEEKDAY(A5,2) -> 3 | D5: =IF(AND(C5>=1,C5<=5,IFERROR(VLOOKUP(A5,$H$2:$H$10,1,0),0)=0),1,0) -> 1 | E5: =MONTH(A5) -> 1 | F5: =IF(IFERROR(VLOOKUP(A5,'Planilla de control'!#REF!,1,0),0)>0,1,0) -> 0 | H5: 44981 | K5: 32 | L5: 0 | P5: 11 | Q5: 22 | U5: 34 | V5: 5
A6: 44931 | B6: =+WEEKNUM(A6) -> 1 | C6: =+WEEKDAY(A6,2) -> 4 | D6: =IF(AND(C6>=1,C6<=5,IFERROR(VLOOKUP(A6,$H$2:$H$10,1,0),0)=0),1,0) -> 1 | E6: =MONTH(A6) -> 1 | F6: =IF(IFERROR(VLOOKUP(A6,'Planilla de control'!#REF!,1,0),0)>0,1,0) -> 0 | H6: 45009 | K6: 33 | L6: 0 | P6: 12 | Q6: 21 | U6: 35 | V6: 4
A7: 44932 | B7: =+WEEKNUM(A7) -> 1 | C7: =+WEEKDAY(A7,2) -> 5 | D7: =IF(AND(C7>=1,C7<=5,IFERROR(VLOOKUP(A7,$H$2:$H$10,1,0),0)=0),1,0) -> 1 | E7: =MONTH(A7) -> 1 | F7: =IF(IFERROR(VLOOKUP(A7,'Planilla de control'!#REF!,1,0),0)>0,1,0) -> 0 | H7: 45023 | K7: 34 | L7: 0 | P7: (en blanco) | U7: 31 | V7: 4
A8: 44933 | B8: =+WEEKNUM(A8) -> 1 | C8: =+WEEKDAY(A8,2) -> 6 | D8: =IF(AND(C8>=1,C8<=5,IFERROR(VLOOKUP(A8,$H$2:$H$10,1,0),0)=0),1,0) -> 0 | E8: =MONTH(A8) -> 1 | F8: =IF(IFERROR(VLOOKUP(A8,'Planilla de control'!#REF!,1,0),0)>0,1,0) -> 0 | H8: 45047 | K8: 35 | L8: 2 | P8: 1 | Q8: 22 | U8: 9 | V8: 21
A9: 44934 | B9: =+WEEKNUM(A9) -> 2 | C9: =+WEEKDAY(A9,2) -> 7 | D9: =IF(AND(C9>=1,C9<=5,IFERROR(VLOOKUP(A9,$H$2:$H$10,1,0),0)=0),1,0) -> 0 | E9: =MONTH(A9) -> 1 | F9: =IF(IFERROR(VLOOKUP(A9,'Planilla de control'!#REF!,1,0),0)>0,1,0) -> 0 | H9: 45071 | K9: 31 | L9: 0 | P9: 2 | Q9: 17 | U9: 35 | V9: 1
A10: 44935 | B10: =+WEEKNUM(A10) -> 2 | C10: =+WEEKDAY(A10,2) -> 1 | D10: =IF(AND(C10>=1,C10<=5,IFERROR(VLOOKUP(A10,$H$2:$H$10,1,0),0)=0),1,0) -> 1 | E10: =MONTH(A10) -> 1 | F10: =IF(IFERROR(VLOOKUP(A10,'Planilla de control'!#REF!,1,0),0)>0,1,0) -> 0 | H10: 45072 | K10: 9 | L10: 1 | P10: 3 | Q10: 22 | U10: 36 | V10: 5
A11: 44936 | B11: =+WEEKNUM(A11) -> 2 | C11: =+WEEKDAY(A11,2) -> 2 | D11: =IF(AND(C11>=1,C11<=5,IFERROR(VLOOKUP(A11,$H$2:$H$10,1,0),0)=0),1,0) -> 1 | E11: =MONTH(A11) -> 1 | F11: =IF(IFERROR(VLOOKUP(A11,'Planilla de control'!#REF!,1,0),0)>0,1,0) -> 0 | H11: 45096 | K11: 35 | L11: 1 | P11: 4 | Q11: 19 | U11: 37 | V11: 5
A12: 44937 | B12: =+WEEKNUM(A12) -> 2 | C12: =+WEEKDAY(A12,2) -> 3 | D12: =IF(AND(C12>=1,C12<=5,IFERROR(VLOOKUP(A12,$H$2:$H$10,1,0),0)=0),1,0) -> 1 | E12: =MONTH(A12) -> 1 | F12: =IF(IFERROR(VLOOKUP(A12,'Planilla de control'!#REF!,1,0),0)>0,1,0) -> 0 | H12: 45097 | K12: 36 | L12: 0 | P12: 5 | Q12: 20 | U12: 38 | V12: 5
A13: 44938 | B13: =+WEEKNUM(A13) -> 2 | C13: =+WEEKDAY(A13,2) -> 4 | D13: =IF(AND(C13>=1,C13<=5,IFERROR(VLOOKUP(A13,$H$2:$H$10,1,0),0)=0),1,0) -> 1 | E13: =MONTH(A13) -> 1 | F13: =IF(IFERROR(VLOOKUP(A13,'Planilla de control'!#REF!,1,0),0)>0,1,0) -> 0 | K13: 37 | L13: 0 | P13: 6 | Q13: 22 | U13: 39 | V13: 5
A14: 44939 | B14: =+WEEKNUM(A14) -> 2 | C14: =+WEEKDAY(A14,2) -> 5 | D14: =IF(AND(C14>=1,C14<=5,IFERROR(VLOOKUP(A14,$H$2:$H$10,1,0),0)=0),1,0) -> 1 | E14: =MONTH(A14) -> 1 | F14: =IF(IFERROR(VLOOKUP(A14,'Planilla de control'!#REF!,1,0),0)>0,1,0) -> 0 | K14: 38 | L14: 0 | P14: 7 | Q14: 21 | U14: 10 | V14: 22
A15: 44940 | B15: =+WEEKNUM(A15) -> 2 | C15: =+WEEKDAY(A15,2) -> 6 | D15: =IF(AND(C15>=1,C15<=5,IFERROR(VLOOKUP(A15,$H$2:$H$10,1,0),0)=0),1,0) -> 0 | E15: =MONTH(A15) -> 1 | F15: =IF(IFERROR(VLOOKUP(A15,'Planilla de control'!#REF!,1,0),0)>0,1,0) -> 0 | K15: 39 | L15: 0 | P15: Total general | Q15: 252 | U15: 40 | V15: 5
A16: 44941 | B16: =+WEEKNUM(A16) -> 3 | C16: =+WEEKDAY(A16,2) -> 7 | D16: =IF(AND(C16>=1,C16<=5,IFERROR(VLOOKUP(A16,$H$2:$H$10,1,0),0)=0),1,0) -> 0 | E16: =MONTH(A16) -> 1 | F16: =IF(IFERROR(VLOOKUP(A16,'Planilla de control'!#REF!,1,0),0)>0,1,0) -> 0 | K16: 10 | L16: 0 | U16: 41 | V16: 5
A17: 44942 | B17: =+WEEKNUM(A17) -> 3 | C17: =+WEEKDAY(A17,2) -> 1 | D17: =IF(AND(C17>=1,C17<=5,IFERROR(VLOOKUP(A17,$H$2:$H$10,1,0),0)=0),1,0) -> 1 | E17: =MONTH(A17) -> 1 | F17: =IF(IFERROR(VLOOKUP(A17,'Planilla de control'!#REF!,1,0),0)>0,1,0) -> 0 | K17: 40 | L17: 0 | U17: 42 | V17: 5
A18: 44943 | B18: =+WEEKNUM(A18) -> 3 | C18: =+WEEKDAY(A18,2) -> 2 | D18: =IF(AND(C18>=1,C18<=5,IFERROR(VLOOKUP(A18,$H$2:$H$10,1,0),0)=0),1,0) -> 1 | E18: =MONTH(A18) -> 1 | F18: =IF(IFERROR(VLOOKUP(A18,'Planilla de control'!#REF!,1,0),0)>0,1,0) -> 0 | K18: 41 | L18: 0 | U18: 43 | V18: 5
A19: 44944 | B19: =+WEEKNUM(A19) -> 3 | C19: =+WEEKDAY(A19,2) -> 3 | D19: =IF(AND(C19>=1,C19<=5,IFERROR(VLOOKUP(A19,$H$2:$H$10,1,0),0)=0),1,0) -> 1 | E19: =MONTH(A19) -> 1 | F19: =IF(IFERROR(VLOOKUP(A19,'Planilla de control'!#REF!,1,0),0)>0,1,0) -> 0 | K19: 42 | L19: 0 | U19: 44 | V19: 2
A20: 44945 | B20: =+WEEKNUM(A20) -> 3 | C20: =+WEEKDAY(A20,2) -> 4 | D20: =IF(AND(C20>=1,C20<=5,IFERROR(VLOOKUP(A20,$H$2:$H$10,1,0),0)=0),1,0) -> 1 | E20: =MONTH(A20) -> 1 | F20: =IF(IFERROR(VLOOKUP(A20,'Planilla de control'!#REF!,1,0),0)>0,1,0) -> 0 | K20: 43 | L20: 0 | U20: 11 | V20: 22
A21: 44946 | B21: =+WEEKNUM(A21) -> 3 | C21: =+WEEKDAY(A21,2) -> 5 | D21: =IF(AND(C21>=1,C21<=5,IFERROR(VLOOKUP(A21,$H$2:$H$10,1,0),0)=0),1,0) -> 1 | E21: =MONTH(A21) -> 1 | F21: =IF(IFERROR(VLOOKUP(A21,'Planilla de control'!#REF!,1,0),0)>0,1,0) -> 0 | K21: 44 | L21: 0 | U21: 44 | V21: 3
A22: 44947 | B22: =+WEEKNUM(A22) -> 3 | C22: =+WEEKDAY(A22,2) -> 6 | D22: =IF(AND(C22>=1,C22<=5,IFERROR(VLOOKUP(A22,$H$2:$H$10,1,0),0)=0),1,0) -> 0 | E22: =MONTH(A22) -> 1 | F22: =IF(IFERROR(VLOOKUP(A22,'Planilla de control'!#REF!,1,0),0)>0,1,0) -> 0 | K22: 11 | L22: 0 | U22: 45 | V22: 5
A23: 44948 | B23: =+WEEKNUM(A23) -> 4 | C23: =+WEEKDAY(A23,2) -> 7 | D23: =IF(AND(C23>=1,C23<=5,IFERROR(VLOOKUP(A23,$H$2:$H$10,1,0),0)=0),1,0) -> 0 | E23: =MONTH(A23) -> 1 | F23: =IF(IFERROR(VLOOKUP(A23,'Planilla de control'!#REF!,1,0),0)>0,1,0) -> 0 | K23: 44 | L23: 0 | U23: 46 | V23: 5
A24: 44949 | B24: =+WEEKNUM(A24) -> 4 | C24: =+WEEKDAY(A24,2) -> 1 | D24: =IF(AND(C24>=1,C24<=5,IFERROR(VLOOKUP(A24,$H$2:$H$10,1,0),0)=0),1,0) -> 1 | E24: =MONTH(A24) -> 1 | F24: =IF(IFERROR(VLOOKUP(A24,'Planilla de control'!#REF!,1,0),0)>0,1,0) -> 0 | K24: 45 | L24: 0 | U24: 47 | V24: 5
A25: 44950 | B25: =+WEEKNUM(A25) -> 4 | C25: =+WEEKDAY(A25,2) -> 2 | D25: =IF(AND(C25>=1,C25<=5,IFERROR(VLOOKUP(A25,$H$2:$H$10,1,0),0)=0),1,0) -> 1 | E25: =MONTH(A25) -> 1 | F25: =IF(IFERROR(VLOOKUP(A25,'Planilla de control'!#REF!,1,0),0)>0,1,0) -> 0 | K25: 46 | L25: 0 | U25: 48 | V25: 4
A26: 44951 | B26: =+WEEKNUM(A26) -> 4 | C26: =+WEEKDAY(A26,2) -> 3 | D26: =IF(AND(C26>=1,C26<=5,IFERROR(VLOOKUP(A26,$H$2:$H$10,1,0),0)=0),1,0) -> 1 | E26: =MONTH(A26) -> 1 | F26: =IF(IFERROR(VLOOKUP(A26,'Planilla de control'!#REF!,1,0),0)>0,1,0) -> 0 | K26: 47 | L26: 0 | U26: 12 | V26: 21
A27: 44952 | B27: =+WEEKNUM(A27) -> 4 | C27: =+WEEKDAY(A27,2) -> 4 | D27: =IF(AND(C27>=1,C27<=5,IFERROR(VLOOKUP(A27,$H$2:$H$10,1,0),0)=0),1,0) -> 1 | E27: =MONTH(A27) -> 1 | F27: =IF(IFERROR(VLOOKUP(A27,'Planilla de control'!#REF!,1,0),0)>0,1,0) -> 0 | K27: 48 | L27: 0 | U27: 48 | V27: 1
... A32: 44957 | B32: =+WEEKNUM(A32) -> 5 | C32: =+WEEKDAY(A32,2) -> 2 | D32: =IF(AND(C32>=1,C32<=5,IFERROR(VLOOKUP(A32,$H$2:$H$10,1,0),0)=0),1,0) -> 1 | E32: =MONTH(A32) -> 1 | F32: =IF(IFERROR(VLOOKUP(A32,'Planilla de control'!#REF!,1,0),0)>0,1,0) -> 0 | K32: 51 | L32: 0 | U32: 53 | V32: 0
A33: 44958 | B33: =+WEEKNUM(A33) -> 5 | C33: =+WEEKDAY(A33,2) -> 3 | D33: =IF(AND(C33>=1,C33<=5,IFERROR(VLOOKUP(A33,$H$2:$H$10,1,0),0)=0),1,0) -> 1 | E33: =MONTH(A33) -> 2 | F33: =IF(IFERROR(VLOOKUP(A33,'Planilla de control'!#REF!,1,0),0)>0,1,0) -> 0 | K33: 52 | L33: 0 | U33: (en blanco)
A34: 44959 | B34: =+WEEKNUM(A34) -> 5 | C34: =+WEEKDAY(A34,2) -> 4 | D34: =IF(AND(C34>=1,C34<=5,IFERROR(VLOOKUP(A34,$H$2:$H$10,1,0),0)=0),1,0) -> 1 | E34: =MONTH(A34) -> 2 | F34: =IF(IFERROR(VLOOKUP(A34,'Planilla de control'!#REF!,1,0),0)>0,1,0) -> 0 | K34: 53 | L34: 0 | U34: (en blanco)
A35: 44960 | B35: =+WEEKNUM(A35) -> 5 | C35: =+WEEKDAY(A35,2) -> 5 | D35: =IF(AND(C35>=1,C35<=5,IFERROR(VLOOKUP(A35,$H$2:$H$10,1,0),0)=0),1,0) -> 1 | E35: =MONTH(A35) -> 2 | F35: =IF(IFERROR(VLOOKUP(A35,'Planilla de control'!#REF!,1,0),0)>0,1,0) -> 0 | K35: (en blanco) | U35: 1 | V35: 22
A36: 44961 | B36: =+WEEKNUM(A36) -> 5 | C36: =+WEEKDAY(A36,2) -> 6 | D36: =IF(AND(C36>=1,C36<=5,IFERROR(VLOOKUP(A36,$H$2:$H$10,1,0),0)=0),1,0) -> 0 | E36: =MONTH(A36) -> 2 | F36: =IF(IFERROR(VLOOKUP(A36,'Planilla de control'!#REF!,1,0),0)>0,1,0) -> 0 | K36: (en blanco) | U36: 1 | V36: 5
A37: 44962 | B37: =+WEEKNUM(A37) -> 6 | C37: =+WEEKDAY(A37,2) -> 7 | D37: =IF(AND(C37>=1,C37<=5,IFERROR(VLOOKUP(A37,$H$2:$H$10,1,0),0)=0),1,0) -> 0 | E37: =MONTH(A37) -> 2 | F37: =IF(IFERROR(VLOOKUP(A37,'Planilla de control'!#REF!,1,0),0)>0,1,0) -> 0 | K37: 1 | L37: 0 | U37: 2 | V37: 5
A38: 44963 | B38: =+WEEKNUM(A38) -> 6 | C38: =+WEEKDAY(A38,2) -> 1 | D38: =IF(AND(C38>=1,C38<=5,IFERROR(VLOOKUP(A38,$H$2:$H$10,1,0),0)=0),1,0) -> 1 | E38: =MONTH(A38) -> 2 | F38: =IF(IFERROR(VLOOKUP(A38,'Planilla de control'!#REF!,1,0),0)>0,1,0) -> 0 | K38: 1 | L38: 0 | U38: 3 | V38: 5
A39: 44964 | B39: =+WEEKNUM(A39) -> 6 | C39: =+WEEKDAY(A39,2) -> 2 | D39: =IF(AND(C39>=1,C39<=5,IFERROR(VLOOKUP(A39,$H$2:$H$10,1,0),0)=0),1,0) -> 1 | E39: =MONTH(A39) -> 2 | F39: =IF(IFERROR(VLOOKUP(A39,'Planilla de control'!#REF!,1,0),0)>0,1,0) -> 0 | K39: 2 | L39: 0 | U39: 4 | V39: 5
A40: 44965 | B40: =+WEEKNUM(A40) -> 6 | C40: =+WEEKDAY(A40,2) -> 3 | D40: =IF(AND(C40>=1,C40<=5,IFERROR(VLOOKUP(A40,$H$2:$H$10,1,0),0)=0),1,0) -> 1 | E40: =MONTH(A40) -> 2 | F40: =IF(IFERROR(VLOOKUP(A40,'Planilla de control'!#REF!,1,0),0)>0,1,0) -> 0 | K40: 3 | L40: 0 | U40: 5 | V40: 2
A41: 44966 | B41: =+WEEKNUM(A41) -> 6 | C41: =+WEEKDAY(A41,2) -> 4 | D41: =IF(AND(C41>=1,C41<=5,IFERROR(VLOOKUP(A41,$H$2:$H$10,1,0),0)=0),1,0) -> 1 | E41: =MONTH(A41) -> 2 | F41: =IF(IFERROR(VLOOKUP(A41,'Planilla de control'!#REF!,1,0),0)>0,1,0) -> 0 | K41: 4 | L41: 0 | U41: 2 | V41: 17
A42: 44967 | B42: =+WEEKNUM(A42) -> 6 | C42: =+WEEKDAY(A42,2) -> 5 | D42: =IF(AND(C42>=1,C42<=5,IFERROR(VLOOKUP(A42,$H$2:$H$10,1,0),0)=0),1,0) -> 1 | E42: =MONTH(A42) -> 2 | F42: =IF(IFERROR(VLOOKUP(A42,'Planilla de control'!#REF!,1,0),0)>0,1,0) -> 0 | K42: 5 | L42: 0 | U42: 5 | V42: 3
A43: 44968 | B43: =+WEEKNUM(A43) -> 6 | C43: =+WEEKDAY(A43,2) -> 6 | D43: =IF(AND(C43>=1,C43<=5,IFERROR(VLOOKUP(A43,$H$2:$H$10,1,0),0)=0),1,0) -> 0 | E43: =MONTH(A43) -> 2 | F43: =IF(IFERROR(VLOOKUP(A43,'Planilla de control'!#REF!,1,0),0)>0,1,0) -> 0 | K43: 2 | L43: 0 | U43: 6 | V43: 5
A44: 44969 | B44: =+WEEKNUM(A44) -> 7 | C44: =+WEEKDAY(A44,2) -> 7 | D44: =IF(AND(C44>=1,C44<=5,IFERROR(VLOOKUP(A44,$H$2:$H$10,1,0),0)=0),1,0) -> 0 | E44: =MONTH(A44) -> 2 | F44: =IF(IFERROR(VLOOKUP(A44,'Planilla de control'!#REF!,1,0),0)>0,1,0) -> 0 | K44: 5 | L44: 0 | U44: 7 | V44: 5
...

Sheet TD
A3: Mes | B3: Deposito | C3: Semana | D3: Fecha control | E3: Ubicación | F3: Count of OK | G3: Count of A -Ub vacia - sap ocup | H3: Count of B -Ub ocup- sap vacía | I3: Count of C -Dif HU | J3: Count of D -Error cant | K3: corregir
A4: ENERO | B4: D3 | C4: 2 | D4: 46027 | E4: 54A1A | F4: 1 | G4: 1 | H4: 1 | I4: 1 | J4: 1 | K4: =+COUNT(F4:J4) -> 5
A5: ENERO | B5: D3 | C5: 2 | D5: 46027 | E5: 54A2A | F5: 1 | G5: 1 | H5: 1 | I5: 1 | J5: 1 | K5: =+COUNT(F5:J5) -> 5
A6: ENERO | B6: D3 | C6: 2 | D6: 46027 | E6: 54A2B | F6: 1 | G6: 1 | H6: 1 | I6: 1 | J6: 1 | K6: =+COUNT(F6:J6) -> 5
A7: ENERO | B7: D3 | C7: 2 | D7: 46027 | E7: 54B1A | F7: 1 | G7: 1 | H7: 1 | I7: 1 | J7: 1 | K7: =+COUNT(F7:J7) -> 5
A8: ENERO | B8: D3 | C8: 2 | D8: 46027 | E8: 54B2A | F8: 1 | G8: 1 | H8: 1 | I8: 1 | J8: 1 | K8: =+COUNT(F8:J8) -> 5
A9: ENERO | B9: D3 | C9: 2 | D9: 46027 | E9: 54B2B | F9: 1 | G9: 1 | H9: 1 | I9: 1 | J9: 1 | K9: =+COUNT(F9:J9) -> 5
A10: ENERO | B10: D3 | C10: 2 | D10: 46027 | E10: 54C1A | F10: 1 | G10: 1 | H10: 1 | I10: 1 | J10: 1 | K10: =+COUNT(F10:J10) -> 5
A11: ENERO | B11: D3 | C11: 2 | D11: 46027 | E11: 54C2A | F11: 1 | G11: 1 | H11: 1 | I11: 1 | J11: 1 | K11: =+COUNT(F11:J11) -> 5
A12: ENERO | B12: D3 | C12: 2 | D12: 46027 | E12: 54C2B | F12: 1 | G12: 1 | H12: 1 | I12: 1 | J12: 1 | K12: =+COUNT(F12:J12) -> 5
A13: ENERO | B13: D3 | C13: 2 | D13: 46027 | E13: 54D1A | F13: 1 | G13: 1 | H13: 1 | I13: 1 | J13: 1 | K13: =+COUNT(F13:J13) -> 5
A14: ENERO | B14: D3 | C14: 2 | D14: 46027 | E14: 54D2A | F14: 1 | G14: 1 | H14: 1 | I14: 1 | J14: 1 | K14: =+COUNT(F14:J14) -> 5
A15: ENERO | B15: D3 | C15: 2 | D15: 46027 | E15: 54D2B | F15: 1 | G15: 1 | H15: 1 | I15: 1 | J15: 1 | K15: =+COUNT(F15:J15) -> 5
... A1408: ENERO | B1408: D3 | C1408: 2 | D1408: 46031 | E1408: 57N7B | F1408: 1 | G1408: 1 | H1408: 1 | I1408: 1 | J1408: 1 | K1408: =+COUNT(F1408:J1408) -> 5
K1409: =+COUNT(F1409:J1409) -> 0
K1410: =+COUNT(F1410:J1410) -> 0
K1411: =+COUNT(F1411:J1411) -> 0
K1412: =+COUNT(F1412:J1412) -> 0
K1413: =+COUNT(F1413:J1413) -> 0
K1414: =+COUNT(F1414:J1414) -> 0
K1415: =+COUNT(F1415:J1415) -> 0
K1416: =+COUNT(F1416:J1416) -> 0
K1417: =+COUNT(F1417:J1417) -> 0
K1418: =+COUNT(F1418:J1418) -> 0
K1419: =+COUNT(F1419:J1419) -> 0
K1420: =+COUNT(F1420:J1420) -> 0
... K8202: =+COUNT(F8202:J8202) -> 0

Sheet TD errores
A1: OK | B1: (Todas)
A3: Mes | B3: Deposito | C3: Ubicación | D3: Suma de Material en otro lugar | E3: Average of Material pagado sin dar de baja | F3: Average of Error de cantidad | G3: Average of Material mal identificado | H3: Average of Material dado de baja | I3: Average of Material no confirmado
A4: (en blanco)
A5: ENERO | B5: D3 | C5: 54A1A
A6: ENERO | B6: D3 | C6: 54A2A
A7: ENERO | B7: D3 | C7: 54A2B
A8: ENERO | B8: D3 | C8: 54A3A
A9: ENERO | B9: D3 | C9: 54A3B
A10: ENERO | B10: D3 | C10: 54B1A
A11: ENERO | B11: D3 | C11: 54B2A
A12: ENERO | B12: D3 | C12: 54B2B
A13: ENERO | B13: D3 | C13: 54B3A
A14: ENERO | B14: D3 | C14: 54B3B
A15: ENERO | B15: D3 | C15: 54C1A
A16: ENERO | B16: D3 | C16: 54C2A
... A658: ENERO | B658: D3 | C658: 54D1B
A659: ENERO | B659: D3 | C659: 54D1D BIS | E659: 1
A660: ENERO | B660: D3 | C660: 54E1B
A661: ENERO | B661: D3 | C661: 54E1D BIS
A662: ENERO | B662: D3 | C662: 54F1B
A663: ENERO | B663: D3 | C663: 54F1D BIS
A664: ENERO | B664: D3 | C664: 54G1B
A665: ENERO | B665: D3 | C665: 54G1D BIS
A666: ENERO | B666: D3 | C666: 54H1B
A667: ENERO | B667: D3 | C667: 54H1D BIS
A668: ENERO | B668: D3 | C668: 54I1B
A669: ENERO | B669: D3 | C669: 54I1D BIS
A670: ENERO | B670: D3 | C670: 54J1B
A671: ENERO | B671: D3 | C671: 54J1D BIS
... A766: ENERO | B766: D3 | C766: 54B1C BIS
A767: ENERO | B767: D3 | C767: 54B1D | F767: 1
A768: ENERO | B768: D3 | C768: 54B2C
A769: ENERO | B769: D3 | C769: 54B2D
A770: ENERO | B770: D3 | C770: 54B3C
A771: ENERO | B771: D3 | C771: 54B3D
A772: ENERO | B772: D3 | C772: 54B4C
A773: ENERO | B773: D3 | C773: 54B4D
A774: ENERO | B774: D3 | C774: 54B5C
A775: ENERO | B775: D3 | C775: 54B5D
A776: ENERO | B776: D3 | C776: 54C1A BIS
...

Sheet Planilla de control
A1: Tipo almacén | B1: Ubicación | C1: Material | D1: Unidad almacén | E1: Bloqueo de entradas | F1: Stock disponible | G1: Stock a entrar | H1: OK | I1: A -Ub vacia - SAP ocup | J1: B -Ub ocup- SAP vacía | K1: C -Dif HU | L1: D -Error cant | M1: COMENTARIO / OTRO | N1: STATUS_APPSHEET
A2: 1FO | B2: 54A2A | C2: 02T409155G0R01 | D2: 09001467827484 | F2: 120 | G2: 0 | H2: X | N2: OK

Sheet PARA MIX CAMIONES
A1: Tipo almacén | B1: Ubicación | C1: Material | D1: Unidad almacén | E1: Bloqueo de entradas | F1: Stock disponible | G1: Stock a entrar | H1: Último movimiento | I1: Motivo bloqueo | J1: CONCATENAR
A2: PCA | B2: 71A1A | C2: 2T2601011P | D2: 09001467086529 | F2: 4 | G2: 0 | H2: 45972 | J2: =CONCATENATE(B2,D2) -> 71A1A09001467086529
A3: PCA | B3: 71A1B | C3: 2T2601011P | D3: 09001467086495 | F3: 4 | G3: 0 | H3: 45972 | J3: =CONCATENATE(B3,D3) -> 71A1B09001467086495
A4: PCA | B4: 71A2A | C4: 23H121333 | D4: 09001460806945 | F4: 1 | G4: 0 | H4: 45972 | J4: =CONCATENATE(B4,D4) -> 71A2A09001460806945
A5: PCA | B5: 71A2A BIS | C5: 2T2411102D | D5: 09001463582331 | F5: 1 | G5: 0 | H5: 45919 | J5: =CONCATENATE(B5,D5) -> 71A2A BIS09001463582331
A6: PCA | B6: 71A3A | C6: << vacías >> | F6: 0 | G6: 0 | J6: =CONCATENATE(B6,D6) -> 71A3A
A7: PCA | B7: 71A4A | C7: 23H121333 | D7: 09001466522721 | F7: 1 | G7: 0 | H7: 46001 | J7: =CONCATENATE(B7,D7) -> 71A4A09001466522721
A8: PCA | B8: 71A5A | C8: 23B400019C | D8: 09001462604722 | F8: 1 | G8: 0 | H8: 45952 | J8: =CONCATENATE(B8,D8) -> 71A5A09001462604722
A9: PCA | B9: 71A6A | C9: 2T2400019AD | D9: 09001461813119 | F9: 1 | G9: 0 | H9: 45881 | J9: =CONCATENATE(B9,D9) -> 71A6A09001461813119
A10: PCA | B10: 71B1A | C10: << vacías >> | F10: 0 | G10: 0 | J10: =CONCATENATE(B10,D10) -> 71B1A
A11: PCA | B11: 71B1B | C11: << vacías >> | F11: 0 | G11: 0 | J11: =CONCATENATE(B11,D11) -> 71B1B
A12: PCA | B12: 71B1C | C12: << vacías >> | F12: 0 | G12: 0 | J12: =CONCATENATE(B12,D12) -> 71B1C
A13: PCA | B13: 71B2A | C13: << vacías >> | F13: 0 | G13: 0 | J13: =CONCATENATE(B13,D13) -> 71B2A
A14: PCA | B14: 71B2A BIS | C14: 23H121333 | D14: 09001467303638 | F14: 1 | G14: 0 | H14: 46002 | J14: =CONCATENATE(B14,D14) -> 71B2A BIS09001467303638
A15: PCA | B15: 71B2A BIS | C15: 23H121333 | D15: 09001467303639 | F15: 1 | G15: 0 | H15: 46002 | J15: =CONCATENATE(B15,D15) -> 71B2A BIS09001467303639
A16: PCA | B16: 71B3A | C16: << vacías >> | F16: 0 | G16: 0 | J16: =CONCATENATE(B16,D16) -> 71B3A
A17: PCA | B17: 71B4A | C17: 2R2863631D | D17: 09001466522970 | F17: 1 | G17: 0 | H17: 45974 | J17: =CONCATENATE(B17,D17) -> 71B4A09001466522970
A18: PCA | B18: 71B5A | C18: << vacías >> | F18: 0 | G18: 0 | J18: =CONCATENATE(B18,D18) -> 71B5A
A19: PCA | B19: 71B6A | C19: << vacías >> | F19: 0 | G19: 0 | J19: =CONCATENATE(B19,D19) -> 71B6A
A20: PCA | B20: 71C1A | C20: << vacías >> | F20: 0 | G20: 0 | J20: =CONCATENATE(B20,D20) -> 71C1A
A21: PCA | B21: 71C1B | C21: << vacías >> | F21: 0 | G21: 0 | J21: =CONCATENATE(B21,D21) -> 71C1B
A22: PCA | B22: 71C1C | C22: << vacías >> | F22: 0 | G22: 0 | J22: =CONCATENATE(B22,D22) -> 71C1C
A23: PCA | B23: 71C2A | C23: 23H121333 | D23: 09001467303641 | F23: 1 | G23: 0 | H23: 46002 | J23: =CONCATENATE(B23,D23) -> 71C2A09001467303641
A24: PCA | B24: 71C2A BIS | C24: << vacías >> | F24: 0 | G24: 0 | J24: =CONCATENATE(B24,D24) -> 71C2A BIS
A25: PCA | B25: 71C3A | C25: 2RD201737 | D25: 09001467212881 | F25: 72 | G25: 0 | H25: 45976 | J25: =CONCATENATE(B25,D25) -> 71C3A09001467212881
A26: PCA | B26: 71C4A | C26: << vacías >> | F26: 0 | G26: 0 | J26: =CONCATENATE(B26,D26) -> 71C4A
A27: PCA | B27: 71C5A | C27: << vacías >> | F27: 0 | G27: 0 | J27: =CONCATENATE(B27,D27) -> 71C5A
A28: PCA | B28: 71C6A | C28: << vacías >> | F28: 0 | G28: 0 | J28: =CONCATENATE(B28,D28) -> 71C6A
A29: PCA | B29: 71D1A | C29: << vacías >> | F29: 0 | G29: 0 | J29: =CONCATENATE(B29,D29) -> 71D1A
A30: PCA | B30: 71D1B | C30: << vacías >> | F30: 0 | G30: 0 | J30: =CONCATENATE(B30,D30) -> 71D1B
A31: PCA | B31: 71D1C | C31: << vacías >> | F31: 0 | G31: 0 | J31: =CONCATENATE(B31,D31) -> 71D1C
A32: PCA | B32: 71D2A | C32: 23H121333 | D32: 09001467310649 | F32: 1 | G32: 0 | H32: 46002 | J32: =CONCATENATE(B32,D32) -> 71D2A09001467310649
A33: PCA | B33: 71D2A BIS | C33: 23H121333 | D33: 09001467310648 | F33: 1 | G33: 0 | H33: 46002 | J33: =CONCATENATE(B33,D33) -> 71D2A BIS09001467310648
A34: PCA | B34: 71D3A | C34: << vacías >> | F34: 0 | G34: 0 | J34: =CONCATENATE(B34,D34) -> 71D3A
A35: PCA | B35: 71D4A | C35: << vacías >> | F35: 0 | G35: 0 | J35: =CONCATENATE(B35,D35) -> 71D4A
A36: PCA | B36: 71D5A | C36: << vacías >> | F36: 0 | G36: 0 | J36: =CONCATENATE(B36,D36) -> 71D5A
A37: PCA | B37: 71D6A | C37: << vacías >> | F37: 0 | G37: 0 | J37: =CONCATENATE(B37,D37) -> 71D6A
A38: PCA | B38: 71E1A | C38: 23B121249F | D38: 09001466972273 | F38: 2 | G38: 0 | H38: 45954 | J38: =CONCATENATE(B38,D38) -> 71E1A09001466972273
A39: PCA | B39: 71E1B | C39: 23B121249F | D39: 09001467091496 | F39: 2 | G39: 0 | H39: 45978 | J39: =CONCATENATE(B39,D39) -> 71E1B09001467091496
A40: PCA | B40: 71E2A | C40: << vacías >> | F40: 0 | G40: 0 | J40: =CONCATENATE(B40,D40) -> 71E2A
...

Sheet Hoja2
A1: 21A1B
A2: 21A1C
A3: 21I1A
A4: 21I2A
A5: 22D3A
A6: 22I1C
A7: 23A1B
A8: 23C2C
A9: 23E2C
A10: 23H2C
A11: 23H3C
A12: 23I1C
... A42: 04L3C

Sheet Ub inicio 
O1: PC2 | P1: RAB | Q1: PC5 | R1: 1FO | S1: 1CT | T1: PCD | U1: RDU
A2: Tipo almacén | B2: Ubicación | C2: Bloqueo de salidas | D2: Bloqueo de entradas | E2: Motivo bloqueo | F2: calle, modulo y nivel | G2: Nivel | H2: Calle | I2: Alveolo | J2: Deposito | L2: FECHA | M2: AUDITADO | O2: MQ200 | P2: MQ200 | Q2: MQ250 | R2: D3 | S2: D4 | T2: DUCATI | U2: DUCATI
A3: PC2 | B3: 01I6B | F3: =IF(OR(LEN(B3)=9,LEN(B3)=5),MID(B3,1,4),MID(B3,1,5)) -> 01I6 | G3: =IF(MID(F3,5,1)<>"",MID(F3,4,2),MID(F3,4,1))*1 -> 6 | H3: =+MID(B3,1,2)*1 -> 1 | I3: =+MID(B3,3,1) -> I | J3: =HLOOKUP(A3,$O$1:$U$2,2,0) -> MQ200 | K3: =CONCATENATE(A3,B3) -> PC201I6B | L3: =VLOOKUP(K3,'Planilla de control'!#REF!,2,0) -> #REF! | M3: =IF(COUNTIF('Planilla de control'!#REF!,K3)>0,"SI","NO") -> #REF! | P3: =COUNTIF($J:$J,P2) -> 2334 | Q3: =COUNTIF($J:$J,Q2) -> 1594 | R3: =COUNTIF($J:$J,R2) -> 2658 | S3: =COUNTIF($J:$J,S2) -> 278 | T3: =COUNTIF($J:$J,T2) -> 536
A4: PC2 | B4: 01I6C | F4: =IF(OR(LEN(B4)=9,LEN(B4)=5),MID(B4,1,4),MID(B4,1,5)) -> 01I6 | G4: =IF(MID(F4,5,1)<>"",MID(F4,4,2),MID(F4,4,1))*1 -> 6 | H4: =+MID(B4,1,2)*1 -> 1 | I4: =+MID(B4,3,1) -> I | J4: =HLOOKUP(A4,$O$1:$U$2,2,0) -> MQ200 | K4: =CONCATENATE(A4,B4) -> PC201I6C | L4: =VLOOKUP(K4,'Planilla de control'!#REF!,2,0) -> #REF! | M4: =IF(COUNTIF('Planilla de control'!#REF!,K4)>0,"SI","NO") -> #REF! | P4: 2334 | Q4: 2241 | R4: 2659 | S4: 266 | T4: 0
A5: PC2 | B5: 01J1A BIS | F5: =IF(OR(LEN(B5)=9,LEN(B5)=5),MID(B5,1,4),MID(B5,1,5)) -> 01J1 | G5: =IF(MID(F5,5,1)<>"",MID(F5,4,2),MID(F5,4,1))*1 -> 1 | H5: =+MID(B5,1,2)*1 -> 1 | I5: =+MID(B5,3,1) -> J | J5: =HLOOKUP(A5,$O$1:$U$2,2,0) -> MQ200 | K5: =CONCATENATE(A5,B5) -> PC201J1A BIS | L5: =VLOOKUP(K5,'Planilla de control'!#REF!,2,0) -> #REF! | M5: =IF(COUNTIF('Planilla de control'!#REF!,K5)>0,"SI","NO") -> #REF!
A6: PC2 | B6: 01J1B BIS | F6: =IF(OR(LEN(B6)=9,LEN(B6)=5),MID(B6,1,4),MID(B6,1,5)) -> 01J1 | G6: =IF(MID(F6,5,1)<>"",MID(F6,4,2),MID(F6,4,1))*1 -> 1 | H6: =+MID(B6,1,2)*1 -> 1 | I6: =+MID(B6,3,1) -> J | J6: =HLOOKUP(A6,$O$1:$U$2,2,0) -> MQ200 | K6: =CONCATENATE(A6,B6) -> PC201J1B BIS | L6: =VLOOKUP(K6,'Planilla de control'!#REF!,2,0) -> #REF! | M6: =IF(COUNTIF('Planilla de control'!#REF!,K6)>0,"SI","NO") -> #REF!
A7: PC2 | B7: 01J2A BIS | F7: =IF(OR(LEN(B7)=9,LEN(B7)=5),MID(B7,1,4),MID(B7,1,5)) -> 01J2 | G7: =IF(MID(F7,5,1)<>"",MID(F7,4,2),MID(F7,4,1))*1 -> 2 | H7: =+MID(B7,1,2)*1 -> 1 | I7: =+MID(B7,3,1) -> J | J7: =HLOOKUP(A7,$O$1:$U$2,2,0) -> MQ200 | K7: =CONCATENATE(A7,B7) -> PC201J2A BIS | L7: =VLOOKUP(K7,'Planilla de control'!#REF!,2,0) -> #REF! | M7: =IF(COUNTIF('Planilla de control'!#REF!,K7)>0,"SI","NO") -> #REF!
A8: PC2 | B8: 01J2B | F8: =IF(OR(LEN(B8)=9,LEN(B8)=5),MID(B8,1,4),MID(B8,1,5)) -> 01J2 | G8: =IF(MID(F8,5,1)<>"",MID(F8,4,2),MID(F8,4,1))*1 -> 2 | H8: =+MID(B8,1,2)*1 -> 1 | I8: =+MID(B8,3,1) -> J | J8: =HLOOKUP(A8,$O$1:$U$2,2,0) -> MQ200 | K8: =CONCATENATE(A8,B8) -> PC201J2B | L8: =VLOOKUP(K8,'Planilla de control'!#REF!,2,0) -> #REF! | M8: =IF(COUNTIF('Planilla de control'!#REF!,K8)>0,"SI","NO") -> #REF!
A9: PC2 | B9: 01J2B BIS | F9: =IF(OR(LEN(B9)=9,LEN(B9)=5),MID(B9,1,4),MID(B9,1,5)) -> 01J2 | G9: =IF(MID(F9,5,1)<>"",MID(F9,4,2),MID(F9,4,1))*1 -> 2 | H9: =+MID(B9,1,2)*1 -> 1 | I9: =+MID(B9,3,1) -> J | J9: =HLOOKUP(A9,$O$1:$U$2,2,0) -> MQ200 | K9: =CONCATENATE(A9,B9) -> PC201J2B BIS | L9: =VLOOKUP(K9,'Planilla de control'!#REF!,2,0) -> #REF! | M9: =IF(COUNTIF('Planilla de control'!#REF!,K9)>0,"SI","NO") -> #REF!
A10: PC2 | B10: 01K1A BIS | F10: =IF(OR(LEN(B10)=9,LEN(B10)=5),MID(B10,1,4),MID(B10,1,5)) -> 01K1 | G10: =IF(MID(F10,5,1)<>"",MID(F10,4,2),MID(F10,4,1))*1 -> 1 | H10: =+MID(B10,1,2)*1 -> 1 | I10: =+MID(B10,3,1) -> K | J10: =HLOOKUP(A10,$O$1:$U$2,2,0) -> MQ200 | K10: =CONCATENATE(A10,B10) -> PC201K1A BIS | L10: =VLOOKUP(K10,'Planilla de control'!#REF!,2,0) -> #REF! | M10: =IF(COUNTIF('Planilla de control'!#REF!,K10)>0,"SI","NO") -> #REF!
A11: PC2 | B11: 01K1B BIS | F11: =IF(OR(LEN(B11)=9,LEN(B11)=5),MID(B11,1,4),MID(B11,1,5)) -> 01K1 | G11: =IF(MID(F11,5,1)<>"",MID(F11,4,2),MID(F11,4,1))*1 -> 1 | H11: =+MID(B11,1,2)*1 -> 1 | I11: =+MID(B11,3,1) -> K | J11: =HLOOKUP(A11,$O$1:$U$2,2,0) -> MQ200 | K11: =CONCATENATE(A11,B11) -> PC201K1B BIS | L11: =VLOOKUP(K11,'Planilla de control'!#REF!,2,0) -> #REF! | M11: =IF(COUNTIF('Planilla de control'!#REF!,K11)>0,"SI","NO") -> #REF!
A12: PC2 | B12: 01K1C BIS | F12: =IF(OR(LEN(B12)=9,LEN(B12)=5),MID(B12,1,4),MID(B12,1,5)) -> 01K1 | G12: =IF(MID(F12,5,1)<>"",MID(F12,4,2),MID(F12,4,1))*1 -> 1 | H12: =+MID(B12,1,2)*1 -> 1 | I12: =+MID(B12,3,1) -> K | J12: =HLOOKUP(A12,$O$1:$U$2,2,0) -> MQ200 | K12: =CONCATENATE(A12,B12) -> PC201K1C BIS | L12: =VLOOKUP(K12,'Planilla de control'!#REF!,2,0) -> #REF! | M12: =IF(COUNTIF('Planilla de control'!#REF!,K12)>0,"SI","NO") -> #REF!
A13: PC2 | B13: 01K2A BIS | F13: =IF(OR(LEN(B13)=9,LEN(B13)=5),MID(B13,1,4),MID(B13,1,5)) -> 01K2 | G13: =IF(MID(F13,5,1)<>"",MID(F13,4,2),MID(F13,4,1))*1 -> 2 | H13: =+MID(B13,1,2)*1 -> 1 | I13: =+MID(B13,3,1) -> K | J13: =HLOOKUP(A13,$O$1:$U$2,2,0) -> MQ200 | K13: =CONCATENATE(A13,B13) -> PC201K2A BIS | L13: =VLOOKUP(K13,'Planilla de control'!#REF!,2,0) -> #REF! | M13: =IF(COUNTIF('Planilla de control'!#REF!,K13)>0,"SI","NO") -> #REF!
A14: PC2 | B14: 01K2B BIS | F14: =IF(OR(LEN(B14)=9,LEN(B14)=5),MID(B14,1,4),MID(B14,1,5)) -> 01K2 | G14: =IF(MID(F14,5,1)<>"",MID(F14,4,2),MID(F14,4,1))*1 -> 2 | H14: =+MID(B14,1,2)*1 -> 1 | I14: =+MID(B14,3,1) -> K | J14: =HLOOKUP(A14,$O$1:$U$2,2,0) -> MQ200 | K14: =CONCATENATE(A14,B14) -> PC201K2B BIS | L14: =VLOOKUP(K14,'Planilla de control'!#REF!,2,0) -> #REF! | M14: =IF(COUNTIF('Planilla de control'!#REF!,K14)>0,"SI","NO") -> #REF!
A15: PC2 | B15: 01K2C | F15: =IF(OR(LEN(B15)=9,LEN(B15)=5),MID(B15,1,4),MID(B15,1,5)) -> 01K2 | G15: =IF(MID(F15,5,1)<>"",MID(F15,4,2),MID(F15,4,1))*1 -> 2 | H15: =+MID(B15,1,2)*1 -> 1 | I15: =+MID(B15,3,1) -> K | J15: =HLOOKUP(A15,$O$1:$U$2,2,0) -> MQ200 | K15: =CONCATENATE(A15,B15) -> PC201K2C | L15: =VLOOKUP(K15,'Planilla de control'!#REF!,2,0) -> #REF! | M15: =IF(COUNTIF('Planilla de control'!#REF!,K15)>0,"SI","NO") -> #REF!
A16: PC2 | B16: 01K2C BIS | F16: =IF(OR(LEN(B16)=9,LEN(B16)=5),MID(B16,1,4),MID(B16,1,5)) -> 01K2 | G16: =IF(MID(F16,5,1)<>"",MID(F16,4,2),MID(F16,4,1))*1 -> 2 | H16: =+MID(B16,1,2)*1 -> 1 | I16: =+MID(B16,3,1) -> K | J16: =HLOOKUP(A16,$O$1:$U$2,2,0) -> MQ200 | K16: =CONCATENATE(A16,B16) -> PC201K2C BIS | L16: =VLOOKUP(K16,'Planilla de control'!#REF!,2,0) -> #REF! | M16: =IF(COUNTIF('Planilla de control'!#REF!,K16)>0,"SI","NO") -> #REF!
... A173: PC2 | B173: 02L1A | F173: =IF(OR(LEN(B173)=9,LEN(B173)=5),MID(B173,1,4),MID(B173,1,5)) -> 02L1 | G173: =IF(MID(F173,5,1)<>"",MID(F173,4,2),MID(F173,4,1))*1 -> 1 | H173: =+MID(B173,1,2)*1 -> 2 | I173: =+MID(B173,3,1) -> L | J173: =HLOOKUP(A173,$O$1:$U$2,2,0) -> MQ200 | K173: =CONCATENATE(A173,B173) -> PC202L1A | L173: =VLOOKUP(K173,'Planilla de control'!#REF!,2,0) -> #REF! | M173: =IF(COUNTIF('Planilla de control'!#REF!,K173)>0,"SI","NO") -> #REF!
A174: RAB | B174: 02A2A | E174: T | F174: =IF(OR(LEN(B174)=9,LEN(B174)=5),MID(B174,1,4),MID(B174,1,5)) -> 02A2 | G174: =IF(MID(F174,5,1)<>"",MID(F174,4,2),MID(F174,4,1))*1 -> 2 | H174: =+MID(B174,1,2)*1 -> 2 | I174: =+MID(B174,3,1) -> A | J174: =HLOOKUP(A174,$O$1:$U$2,2,0) -> MQ200 | K174: =CONCATENATE(A174,B174) -> RAB02A2A | L174: =VLOOKUP(K174,'Planilla de control'!#REF!,2,0) -> #REF! | M174: =IF(COUNTIF('Planilla de control'!#REF!,K174)>0,"SI","NO") -> #REF!
A175: RAB | B175: 02A2B | E175: T | F175: =IF(OR(LEN(B175)=9,LEN(B175)=5),MID(B175,1,4),MID(B175,1,5)) -> 02A2 | G175: =IF(MID(F175,5,1)<>"",MID(F175,4,2),MID(F175,4,1))*1 -> 2 | H175: =+MID(B175,1,2)*1 -> 2 | I175: =+MID(B175,3,1) -> A | J175: =HLOOKUP(A175,$O$1:$U$2,2,0) -> MQ200 | K175: =CONCATENATE(A175,B175) -> RAB02A2B | L175: =VLOOKUP(K175,'Planilla de control'!#REF!,2,0) -> #REF! | M175: =IF(COUNTIF('Planilla de control'!#REF!,K175)>0,"SI","NO") -> #REF!
A176: RAB | B176: 02A2C | E176: T | F176: =IF(OR(LEN(B176)=9,LEN(B176)=5),MID(B176,1,4),MID(B176,1,5)) -> 02A2 | G176: =IF(MID(F176,5,1)<>"",MID(F176,4,2),MID(F176,4,1))*1 -> 2 | H176: =+MID(B176,1,2)*1 -> 2 | I176: =+MID(B176,3,1) -> A | J176: =HLOOKUP(A176,$O$1:$U$2,2,0) -> MQ200 | K176: =CONCATENATE(A176,B176) -> RAB02A2C | L176: =VLOOKUP(K176,'Planilla de control'!#REF!,2,0) -> #REF! | M176: =IF(COUNTIF('Planilla de control'!#REF!,K176)>0,"SI","NO") -> #REF!
A177: RAB | B177: 02A3A | E177: T | F177: =IF(OR(LEN(B177)=9,LEN(B177)=5),MID(B177,1,4),MID(B177,1,5)) -> 02A3 | G177: =IF(MID(F177,5,1)<>"",MID(F177,4,2),MID(F177,4,1))*1 -> 3 | H177: =+MID(B177,1,2)*1 -> 2 | I177: =+MID(B177,3,1) -> A | J177: =HLOOKUP(A177,$O$1:$U$2,2,0) -> MQ200 | K177: =CONCATENATE(A177,B177) -> RAB02A3A | L177: =VLOOKUP(K177,'Planilla de control'!#REF!,2,0) -> #REF! | M177: =IF(COUNTIF('Planilla de control'!#REF!,K177)>0,"SI","NO") -> #REF!
A178: RAB | B178: 02A3B | E178: T | F178: =IF(OR(LEN(B178)=9,LEN(B178)=5),MID(B178,1,4),MID(B178,1,5)) -> 02A3 | G178: =IF(MID(F178,5,1)<>"",MID(F178,4,2),MID(F178,4,1))*1 -> 3 | H178: =+MID(B178,1,2)*1 -> 2 | I178: =+MID(B178,3,1) -> A | J178: =HLOOKUP(A178,$O$1:$U$2,2,0) -> MQ200 | K178: =CONCATENATE(A178,B178) -> RAB02A3B | L178: =VLOOKUP(K178,'Planilla de control'!#REF!,2,0) -> #REF! | M178: =IF(COUNTIF('Planilla de control'!#REF!,K178)>0,"SI","NO") -> #REF!
A179: RAB | B179: 02A4A | E179: T | F179: =IF(OR(LEN(B179)=9,LEN(B179)=5),MID(B179,1,4),MID(B179,1,5)) -> 02A4 | G179: =IF(MID(F179,5,1)<>"",MID(F179,4,2),MID(F179,4,1))*1 -> 4 | H179: =+MID(B179,1,2)*1 -> 2 | I179: =+MID(B179,3,1) -> A | J179: =HLOOKUP(A179,$O$1:$U$2,2,0) -> MQ200 | K179: =CONCATENATE(A179,B179) -> RAB02A4A | L179: =VLOOKUP(K179,'Planilla de control'!#REF!,2,0) -> #REF! | M179: =IF(COUNTIF('Planilla de control'!#REF!,K179)>0,"SI","NO") -> #REF!
A180: RAB | B180: 02A4B | E180: T | F180: =IF(OR(LEN(B180)=9,LEN(B180)=5),MID(B180,1,4),MID(B180,1,5)) -> 02A4 | G180: =IF(MID(F180,5,1)<>"",MID(F180,4,2),MID(F180,4,1))*1 -> 4 | H180: =+MID(B180,1,2)*1 -> 2 | I180: =+MID(B180,3,1) -> A | J180: =HLOOKUP(A180,$O$1:$U$2,2,0) -> MQ200 | K180: =CONCATENATE(A180,B180) -> RAB02A4B | L180: =VLOOKUP(K180,'Planilla de control'!#REF!,2,0) -> #REF! | M180: =IF(COUNTIF('Planilla de control'!#REF!,K180)>0,"SI","NO") -> #REF!
A181: RAB | B181: 02A4C | E181: T | F181: =IF(OR(LEN(B181)=9,LEN(B181)=5),MID(B181,1,4),MID(B181,1,5)) -> 02A4 | G181: =IF(MID(F181,5,1)<>"",MID(F181,4,2),MID(F181,4,1))*1 -> 4 | H181: =+MID(B181,1,2)*1 -> 2 | I181: =+MID(B181,3,1) -> A | J181: =HLOOKUP(A181,$O$1:$U$2,2,0) -> MQ200 | K181: =CONCATENATE(A181,B181) -> RAB02A4C | L181: =VLOOKUP(K181,'Planilla de control'!#REF!,2,0) -> #REF! | M181: =IF(COUNTIF('Planilla de control'!#REF!,K181)>0,"SI","NO") -> #REF!
A182: RAB | B182: 02A5A | E182: T | F182: =IF(OR(LEN(B182)=9,LEN(B182)=5),MID(B182,1,4),MID(B182,1,5)) -> 02A5 | G182: =IF(MID(F182,5,1)<>"",MID(F182,4,2),MID(F182,4,1))*1 -> 5 | H182: =+MID(B182,1,2)*1 -> 2 | I182: =+MID(B182,3,1) -> A | J182: =HLOOKUP(A182,$O$1:$U$2,2,0) -> MQ200 | K182: =CONCATENATE(A182,B182) -> RAB02A5A | L182: =VLOOKUP(K182,'Planilla de control'!#REF!,2,0) -> #REF! | M182: =IF(COUNTIF('Planilla de control'!#REF!,K182)>0,"SI","NO") -> #REF!
A183: RAB | B183: 02A5B | E183: T | F183: =IF(OR(LEN(B183)=9,LEN(B183)=5),MID(B183,1,4),MID(B183,1,5)) -> 02A5 | G183: =IF(MID(F183,5,1)<>"",MID(F183,4,2),MID(F183,4,1))*1 -> 5 | H183: =+MID(B183,1,2)*1 -> 2 | I183: =+MID(B183,3,1) -> A | J183: =HLOOKUP(A183,$O$1:$U$2,2,0) -> MQ200 | K183: =CONCATENATE(A183,B183) -> RAB02A5B | L183: =VLOOKUP(K183,'Planilla de control'!#REF!,2,0) -> #REF! | M183: =IF(COUNTIF('Planilla de control'!#REF!,K183)>0,"SI","NO") -> #REF!
A184: RAB | B184: 02A5C | E184: T | F184: =IF(OR(LEN(B184)=9,LEN(B184)=5),MID(B184,1,4),MID(B184,1,5)) -> 02A5 | G184: =IF(MID(F184,5,1)<>"",MID(F184,4,2),MID(F184,4,1))*1 -> 5 | H184: =+MID(B184,1,2)*1 -> 2 | I184: =+MID(B184,3,1) -> A | J184: =HLOOKUP(A184,$O$1:$U$2,2,0) -> MQ200 | K184: =CONCATENATE(A184,B184) -> RAB02A5C | L184: =VLOOKUP(K184,'Planilla de control'!#REF!,2,0) -> #REF! | M184: =IF(COUNTIF('Planilla de control'!#REF!,K184)>0,"SI","NO") -> #REF!
A185: RAB | B185: 02A6A | E185: T | F185: =IF(OR(LEN(B185)=9,LEN(B185)=5),MID(B185,1,4),MID(B185,1,5)) -> 02A6 | G185: =IF(MID(F185,5,1)<>"",MID(F185,4,2),MID(F185,4,1))*1 -> 6 | H185: =+MID(B185,1,2)*1 -> 2 | I185: =+MID(B185,3,1) -> A | J185: =HLOOKUP(A185,$O$1:$U$2,2,0) -> MQ200 | K185: =CONCATENATE(A185,B185) -> RAB02A6A | L185: =VLOOKUP(K185,'Planilla de control'!#REF!,2,0) -> #REF! | M185: =IF(COUNTIF('Planilla de control'!#REF!,K185)>0,"SI","NO") -> #REF!
... A211: RAB | B211: 02B8C | E211: T | F211: =IF(OR(LEN(B211)=9,LEN(B211)=5),MID(B211,1,4),MID(B211,1,5)) -> 02B8 | G211: =IF(MID(F211,5,1)<>"",MID(F211,4,2),MID(F211,4,1))*1 -> 8 | H211: =+MID(B211,1,2)*1 -> 2 | I211: =+MID(B211,3,1) -> B | J211: =HLOOKUP(A211,$O$1:$U$2,2,0) -> MQ200 | K211: =CONCATENATE(A211,B211) -> RAB02B8C | L211: =VLOOKUP(K211,'Planilla de control'!#REF!,2,0) -> #REF! | M211: =IF(COUNTIF('Planilla de control'!#REF!,K211)>0,"SI","NO") -> #REF!
A212: RAB | B212: 02C4A | F212: =IF(OR(LEN(B212)=9,LEN(B212)=5),MID(B212,1,4),MID(B212,1,5)) -> 02C4 | G212: =IF(MID(F212,5,1)<>"",MID(F212,4,2),MID(F212,4,1))*1 -> 4 | H212: =+MID(B212,1,2)*1 -> 2 | I212: =+MID(B212,3,1) -> C | J212: =HLOOKUP(A212,$O$1:$U$2,2,0) -> MQ200 | K212: =CONCATENATE(A212,B212) -> RAB02C4A | L212: =VLOOKUP(K212,'Planilla de control'!#REF!,2,0) -> #REF! | M212: =IF(COUNTIF('Planilla de control'!#REF!,K212)>0,"SI","NO") -> #REF!
A213: RAB | B213: 02C4C | F213: =IF(OR(LEN(B213)=9,LEN(B213)=5),MID(B213,1,4),MID(B213,1,5)) -> 02C4 | G213: =IF(MID(F213,5,1)<>"",MID(F213,4,2),MID(F213,4,1))*1 -> 4 | H213: =+MID(B213,1,2)*1 -> 2 | I213: =+MID(B213,3,1) -> C | J213: =HLOOKUP(A213,$O$1:$U$2,2,0) -> MQ200 | K213: =CONCATENATE(A213,B213) -> RAB02C4C | L213: =VLOOKUP(K213,'Planilla de control'!#REF!,2,0) -> #REF! | M213: =IF(COUNTIF('Planilla de control'!#REF!,K213)>0,"SI","NO") -> #REF!
A214: RAB | B214: 02C5C | F214: =IF(OR(LEN(B214)=9,LEN(B214)=5),MID(B214,1,4),MID(B214,1,5)) -> 02C5 | G214: =IF(MID(F214,5,1)<>"",MID(F214,4,2),MID(F214,4,1))*1 -> 5 | H214: =+MID(B214,1,2)*1 -> 2 | I214: =+MID(B214,3,1) -> C | J214: =HLOOKUP(A214,$O$1:$U$2,2,0) -> MQ200 | K214: =CONCATENATE(A214,B214) -> RAB02C5C | L214: =VLOOKUP(K214,'Planilla de control'!#REF!,2,0) -> #REF! | M214: =IF(COUNTIF('Planilla de control'!#REF!,K214)>0,"SI","NO") -> #REF!
A215: RAB | B215: 02C6C | F215: =IF(OR(LEN(B215)=9,LEN(B215)=5),MID(B215,1,4),MID(B215,1,5)) -> 02C6 | G215: =IF(MID(F215,5,1)<>"",MID(F215,4,2),MID(F215,4,1))*1 -> 6 | H215: =+MID(B215,1,2)*1 -> 2 | I215: =+MID(B215,3,1) -> C | J215: =HLOOKUP(A215,$O$1:$U$2,2,0) -> MQ200 | K215: =CONCATENATE(A215,B215) -> RAB02C6C | L215: =VLOOKUP(K215,'Planilla de control'!#REF!,2,0) -> #REF! | M215: =IF(COUNTIF('Planilla de control'!#REF!,K215)>0,"SI","NO") -> #REF!
A216: RAB | B216: 02F2A | F216: =IF(OR(LEN(B216)=9,LEN(B216)=5),MID(B216,1,4),MID(B216,1,5)) -> 02F2 | G216: =IF(MID(F216,5,1)<>"",MID(F216,4,2),MID(F216,4,1))*1 -> 2 | H216: =+MID(B216,1,2)*1 -> 2 | I216: =+MID(B216,3,1) -> F | J216: =HLOOKUP(A216,$O$1:$U$2,2,0) -> MQ200 | K216: =CONCATENATE(A216,B216) -> RAB02F2A | L216: =VLOOKUP(K216,'Planilla de control'!#REF!,2,0) -> #REF! | M216: =IF(COUNTIF('Planilla de control'!#REF!,K216)>0,"SI","NO") -> #REF!
A217: RAB | B217: 02G2A | E217: T | F217: =IF(OR(LEN(B217)=9,LEN(B217)=5),MID(B217,1,4),MID(B217,1,5)) -> 02G2 | G217: =IF(MID(F217,5,1)<>"",MID(F217,4,2),MID(F217,4,1))*1 -> 2 | H217: =+MID(B217,1,2)*1 -> 2 | I217: =+MID(B217,3,1) -> G | J217: =HLOOKUP(A217,$O$1:$U$2,2,0) -> MQ200 | K217: =CONCATENATE(A217,B217) -> RAB02G2A | L217: =VLOOKUP(K217,'Planilla de control'!#REF!,2,0) -> #REF! | M217: =IF(COUNTIF('Planilla de control'!#REF!,K217)>0,"SI","NO") -> #REF!
A218: RAB | B218: 02G2B | E218: T | F218: =IF(OR(LEN(B218)=9,LEN(B218)=5),MID(B218,1,4),MID(B218,1,5)) -> 02G2 | G218: =IF(MID(F218,5,1)<>"",MID(F218,4,2),MID(F218,4,1))*1 -> 2 | H218: =+MID(B218,1,2)*1 -> 2 | I218: =+MID(B218,3,1) -> G | J218: =HLOOKUP(A218,$O$1:$U$2,2,0) -> MQ200 | K218: =CONCATENATE(A218,B218) -> RAB02G2B | L218: =VLOOKUP(K218,'Planilla de control'!#REF!,2,0) -> #REF! | M218: =IF(COUNTIF('Planilla de control'!#REF!,K218)>0,"SI","NO") -> #REF!
A219: RAB | B219: 02G2C | E219: T | F219: =IF(OR(LEN(B219)=9,LEN(B219)=5),MID(B219,1,4),MID(B219,1,5)) -> 02G2 | G219: =IF(MID(F219,5,1)<>"",MID(F219,4,2),MID(F219,4,1))*1 -> 2 | H219: =+MID(B219,1,2)*1 -> 2 | I219: =+MID(B219,3,1) -> G | J219: =HLOOKUP(A219,$O$1:$U$2,2,0) -> MQ200 | K219: =CONCATENATE(A219,B219) -> RAB02G2C | L219: =VLOOKUP(K219,'Planilla de control'!#REF!,2,0) -> #REF! | M219: =IF(COUNTIF('Planilla de control'!#REF!,K219)>0,"SI","NO") -> #REF!
A220: RAB | B220: 02H2A | E220: T | F220: =IF(OR(LEN(B220)=9,LEN(B220)=5),MID(B220,1,4),MID(B220,1,5)) -> 02H2 | G220: =IF(MID(F220,5,1)<>"",MID(F220,4,2),MID(F220,4,1))*1 -> 2 | H220: =+MID(B220,1,2)*1 -> 2 | I220: =+MID(B220,3,1) -> H | J220: =HLOOKUP(A220,$O$1:$U$2,2,0) -> MQ200 | K220: =CONCATENATE(A220,B220) -> RAB02H2A | L220: =VLOOKUP(K220,'Planilla de control'!#REF!,2,0) -> #REF! | M220: =IF(COUNTIF('Planilla de control'!#REF!,K220)>0,"SI","NO") -> #REF!
A221: RAB | B221: 02H2B | E221: T | F221: =IF(OR(LEN(B221)=9,LEN(B221)=5),MID(B221,1,4),MID(B221,1,5)) -> 02H2 | G221: =IF(MID(F221,5,1)<>"",MID(F221,4,2),MID(F221,4,1))*1 -> 2 | H221: =+MID(B221,1,2)*1 -> 2 | I221: =+MID(B221,3,1) -> H | J221: =HLOOKUP(A221,$O$1:$U$2,2,0) -> MQ200 | K221: =CONCATENATE(A221,B221) -> RAB02H2B | L221: =VLOOKUP(K221,'Planilla de control'!#REF!,2,0) -> #REF! | M221: =IF(COUNTIF('Planilla de control'!#REF!,K221)>0,"SI","NO") -> #REF!
...

Sheet Plan auditoria y avance
A1: Mes | B1: Dias trabajo | C1: Conteo Buffer | D1: Conteo PT | E1: Dias audit de ubic
A2: Marzo | B2: =GETPIVOTDATA("Cuenta",dias!$P$1,"mes",3) -> 22 | C2: 2 | D2: 2 | E2: =B2-C2-D2 -> 18
A3: Abril | B3: =GETPIVOTDATA("Cuenta",dias!$P$1,"mes",4) -> 19 | C3: 2 | D3: 2 | E3: =B3-C3-D3 -> 15
A5: dias habiles | C5: =GETPIVOTDATA("Cuenta",dias!$U$1,"semana",C11,"mes",3) -> 3 | D5: =GETPIVOTDATA("Cuenta",dias!$U$1,"semana",D11,"mes",3) -> 5 | E5: =GETPIVOTDATA("Cuenta",dias!$U$1,"semana",E11,"mes",3) -> 5 | F5: =GETPIVOTDATA("Cuenta",dias!$U$1,"semana",F11,"mes",3) -> 4 | G5: =GETPIVOTDATA("Cuenta",dias!$U$1,"semana",G11,"mes",3) -> 5 | H5: =GETPIVOTDATA("Cuenta",dias!$U$1,"semana",H11,"mes",4) -> 4 | I5: =GETPIVOTDATA("Cuenta",dias!$U$1,"semana",I11,"mes",4) -> 5 | J5: =GETPIVOTDATA("Cuenta",dias!$U$1,"semana",J11,"mes",4) -> 5 | K5: =GETPIVOTDATA("Cuenta",dias!$U$1,"semana",K11,"mes",4) -> 5 | L5: =GETPIVOTDATA("Cuenta",dias!$U$1,"semana",L11,"mes",4) -> 0
A7: Mes | C7: Marzo | D7: Marzo | E7: Marzo | F7: Marzo | G7: Marzo | H7: Abril | I7: Abril | J7: Abril | K7: Abril | L7: Abril
A8: Dias de conteo | C8: 3 | D8: 5 | E8: 3 | F8: 4 | G8: 3 | H8: 4 | I8: 5 | J8: 4 | K8: 2 | L8: 0
A9: Dias de conteo real | C9: =GETPIVOTDATA("conto?",dias!$K$3,"semana",C11,"mes",3) -> 0 | D9: =GETPIVOTDATA("conto?",dias!$K$3,"semana",D11,"mes",3) -> 0 | E9: =GETPIVOTDATA("conto?",dias!$K$3,"semana",E11,"mes",3) -> 0 | F9: =GETPIVOTDATA("conto?",dias!$K$3,"semana",F11,"mes",3) -> 0 | G9: =GETPIVOTDATA("conto?",dias!$K$3,"semana",G11,"mes",3) -> 0 | H9: =GETPIVOTDATA("conto?",dias!$K$3,"semana",H11,"mes",4) -> 0 | I9: =GETPIVOTDATA("conto?",dias!$K$3,"semana",I11,"mes",4) -> 0 | J9: =GETPIVOTDATA("conto?",dias!$K$3,"semana",J11,"mes",4) -> 0 | K9: =GETPIVOTDATA("conto?",dias!$K$3,"semana",K11,"mes",4) -> 0 | L9: =GETPIVOTDATA("conto?",dias!$K$3,"semana",L11,"mes",4) -> 0
A10: Mes | C10: =A2 -> Marzo | H10: =A3 -> Abril
A11: Semana | B11: Ub total | C11: 9 | D11: 10 | E11: 11 | F11: 12 | G11: 13 | H11: 14 | I11: 15 | J11: 16 | K11: 17 | L11: 18
A12: Planificado | B12: =SUM(Graficos!T9:T19) -> 2810 | C12: =$B$12/SUM($E$2:$E$3)*C8 -> 255.45455 | D12: =$B$12/SUM($E$2:$E$3)*D8 -> 425.75758 | E12: =$B$12/SUM($E$2:$E$3)*E8 -> 255.45455 | F12: =$B$12/SUM($E$2:$E$3)*F8 -> 340.60606 | G12: =$B$12/SUM($E$2:$E$3)*G8 -> 255.45455 | H12: =$B$12/SUM($E$2:$E$3)*H8 -> 340.60606 | I12: =$B$12/SUM($E$2:$E$3)*I8 -> 425.75758 | J12: =$B$12/SUM($E$2:$E$3)*J8 -> 340.60606 | ... L12: =$B$12/SUM($E$2:$E$3)*L8 -> 0
A13: Real | B13: =SUM(C13:L13) -> 0 | C13: =+COUNTIFS(TD!$C:$C,'Plan auditoria y avance'!C11,TD!$A:$A,C7) -> 0 | D13: =+COUNTIFS(TD!$C:$C,'Plan auditoria y avance'!D11,TD!$A:$A,D7) -> 0 | E13: =+COUNTIFS(TD!$C:$C,'Plan auditoria y avance'!E11,TD!$A:$A,E7) -> 0 | F13: =+COUNTIFS(TD!$C:$C,'Plan auditoria y avance'!F11,TD!$A:$A,F7) -> 0 | G13: =+COUNTIFS(TD!$C:$C,'Plan auditoria y avance'!G11,TD!$A:$A,G7) -> 0 | H13: =+COUNTIFS(TD!$C:$C,'Plan auditoria y avance'!H11,TD!$A:$A,H7) -> 0 | I13: =+COUNTIFS(TD!$C:$C,'Plan auditoria y avance'!I11,TD!$A:$A,I7) -> 0 | J13: =+COUNTIFS(TD!$C:$C,'Plan auditoria y avance'!J11,TD!$A:$A,J7) -> 0 | ... L13: =+COUNTIFS(TD!$C:$C,'Plan auditoria y avance'!L11,TD!$A:$A,L7) -> 0
A14: % Cumpl. Semanal | C14: =IFERROR(C13/C12,0) -> 0 | D14: =IFERROR(D13/D12,0) -> 0 | E14: =IFERROR(E13/E12,0) -> 0 | F14: =IFERROR(F13/F12,0) -> 0 | G14: =IFERROR(G13/G12,0) -> 0 | H14: =IFERROR(H13/H12,0) -> 0 | I14: =IFERROR(I13/I12,0) -> 0 | J14: =IFERROR(J13/J12,0) -> 0 | ... L14: =IFERROR(L13/L12,0) -> 0
A15: Plan Acum | C15: =+C12+B15 -> 255.45455 | D15: =+D12+C15 -> 681.21212 | E15: =+E12+D15 -> 936.66667 | F15: =+F12+E15 -> 1277.2727 | G15: =+G12+F15 -> 1532.7273 | H15: =+H12+G15 -> 1873.3333 | I15: =+I12+H15 -> 2299.0909 | J15: =+J12+I15 -> 2639.697 | ... L15: =+L12+K15 -> 2810
A16: % Plan Acum | C16: =+C15/SUM($C$12:$L$12) -> 0.090909091 | D16: =+D15/SUM($C$12:$L$12) -> 0.24242424 | E16: =+E15/SUM($C$12:$L$12) -> 0.33333333 | F16: =+F15/SUM($C$12:$L$12) -> 0.45454545 | G16: =+G15/SUM($C$12:$L$12) -> 0.54545455 | H16: =+H15/SUM($C$12:$L$12) -> 0.66666667 | I16: =+I15/SUM($C$12:$L$12) -> 0.81818182 | J16: =+J15/SUM($C$12:$L$12) -> 0.93939394 | ... L16: =+L15/SUM($C$12:$L$12) -> 1
A17: Real Acum | C17: =+C13+B17 -> 0 | D17: =+D13+C17 -> 0 | E17: =+E13+D17 -> 0 | F17: =+F13+E17 -> 0 | G17: =+G13+F17 -> 0 | H17: =+H13+G17 -> 0 | I17: =+I13+H17 -> 0 | J17: =+J13+I17 -> 0 | ... L17: =+L13+K17 -> 0
A18: % Real Acum | C18: =+C17/SUM($C$12:$L$12) -> 0 | D18: =+D17/SUM($C$12:$L$12) -> 0 | E18: =+E17/SUM($C$12:$L$12) -> 0 | F18: =+F17/SUM($C$12:$L$12) -> 0 | G18: =+G17/SUM($C$12:$L$12) -> 0 | H18: =+H17/SUM($C$12:$L$12) -> 0 | I18: =+I17/SUM($C$12:$L$12) -> 0 | J18: =+J17/SUM($C$12:$L$12) -> 0 | ... L18: =+L17/SUM($C$12:$L$12) -> 0
A19: FALTAN: | C19: =C15-C17 -> 255.45455 | D19: =D15-D17 -> 681.21212 | E19: =E15-E17 -> 936.66667 | F19: =F15-F17 -> 1277.2727 | G19: =G15-G17 -> 1532.7273 | H19: =H15-H17 -> 1873.3333 | I19: =I15-I17 -> 2299.0909 | J19: =J15-J17 -> 2639.697 | ... L19: =L15-L17 -> 2810
A20: % Actual | B20: =B13/B12 -> 0 | C20: =C17/C15 -> 0 | D20: =D17/D15 -> 0 | E20: =E17/E15 -> 0 | F20: =F17/F15 -> 0 | G20: =G17/G15 -> 0 | H20: =H17/H15 -> 0 | I20: =I17/I15 -> 0 | J20: =J17/J15 -> 0 | ... L20: =L17/L15 -> 0
A22: Deposito | B22: =A2 -> Marzo | C22: =A3 -> Abril | D22: =#REF! -> #REF! | E22: Acum | F22: Target
A23: D3 | B23: =IFERROR(COUNTIFS(TD!$B:$B,'Plan auditoria y avance'!$A23,TD!$A:$A,'Plan auditoria y avance'!B$22,TD!$F:$F,">0")/COUNTIFS(TD!$B:$B,'Plan auditoria y avance'!$A23,TD!$A:$A,'Plan auditoria y avance'!B$22),"S/D") -> S/D | C23: =IFERROR(COUNTIFS(TD!$B:$B,'Plan auditoria y avance'!$A23,TD!$A:$A,'Plan auditoria y avance'!C$22,TD!$F:$F,">0")/COUNTIFS(TD!$B:$B,'Plan auditoria y avance'!$A23,TD!$A:$A,'Plan auditoria y avance'!C$22),"S/D") -> S/D | D23: =IFERROR(COUNTIFS(TD!$B:$B,'Plan auditoria y avance'!$A23,TD!$A:$A,'Plan auditoria y avance'!D$22,TD!$F:$F,">0")/COUNTIFS(TD!$B:$B,'Plan auditoria y avance'!$A23,TD!$A:$A,'Plan auditoria y avance'!D$22),"S/D") -> S/D | E23: =IFERROR(COUNTIFS(TD!$B:$B,'Plan auditoria y avance'!A23,TD!$F:$F,">0")/COUNTIF(TD!$B:$B,'Plan auditoria y avance'!A23),"S/D") -> 1 | F23: 0.995
